Workbook

Sheet บันทึกรายเที่ยว
A1: แบบฟอร์มรายงานการขนส่งรายเที่ยว (Template มาตรฐาน v11)
A2: ใส่ข้อมูลตั้งแต่แถวที่ 6 ลงไป กรอกถึงแค่คอลัมน์ K (นน.ปลายทาง) พอ — คอลัมน์ L (ส่วนต่าง) และ M (จ่ายค่าบรรทุก) เป็นสูตร ระบบคิดให้เอง ห้ามพิมพ์ทับ | ถ้าก๊อปมาวาง ให้วางแค่ช่วง A ถึง K และใช้ คลิกขวา > วางแบบพิเศษ > ค่า (Paste Values) เพื่อไม่ให้ทับสูตรและ dropdown ที่ตั้งไว้ | วางเสร็จดูช่อง O10 "ชื่อที่ไม่อยู่ในรายการ" ต้องเป็น 0
A3: ประจำเดือน: | B3: กรกฎาคม 2569 | C3: เลขที่หนังสือ: | E3: นามที่จ่าย (เล่มนี้): | F3: ศิลาชัย
A4: ขั้นตอน: [เหมือง] กรอกหน้านี้ให้ครบ > ดูช่องเตือน O11 ต้องขึ้นว่า ปกติ > เปิด sheet "สรุปเหมือง" ตรวจให้ถูกต้อง (ช่อง I10 ต้องขึ้นว่า ยอดตรงกับรายเที่ยว) แล้วจึงส่งไฟล์ให้ฝ่ายบัญชี | [บัญชี] กรอก sheet "oil" + "อัตราค่าขนส่ง" แล้วตรวจ sheet "สรุปจ่ายรถร่วม" อีกครั้งก่อนพิมพ์ปะหน้า (หน้า oil เป็นของฝ่ายบัญชี เหมืองไม่ต้องกรอก) | N4: ช่องตรวจทาน (ห้ามลบ)
A5: วันที่ | B5: เหมืองต้นทาง | C5: ท่าปลายทาง | D5: ชนิดแร่/หิน | E5: แบก นน. | F5: ทีมรถร่วม | G5: นามที่จ่าย | H5: ทะเบียนรถ | I5: เลขที่ชั่ง | J5: นน.ต้นทาง (ตัน) | K5: นน.ปลายทาง (ตัน) | L5: นน.ส่วนต่าง (ตัน) | M5: นน.จ่ายค่าบรรทุก (ตัน) | N5: จำนวนเที่ยวที่กรอก | O5: =COUNTA($A$6:$A$10005) -> 0 | Q5: stoneLbl | R5: route | S5: key2 | T5: key3 | U5: rtb | V5: accKey | W5: seq3 | X5: 0 | Y5: - | Z5: seqAcc | AA5: 0
L6: =IF(OR($A6="",AND($J6="",$K6="")),"",ROUND(N($J6)-N($K6),2)) | M6: =IF(OR($A6="",AND($J6="",$K6="")),"",MIN($J6,$K6)) | N6: รวม นน.จ่ายค่าบรรทุก (ตัน) | O6: =ROUND(SUM($M$6:$M$10005),2) -> 0 | Q6: =IF($A6="","",$D6&"("&SUBSTITUTE($E6," ","")&")") | R6: =IF($A6="","",$B6&" - "&$C6) | S6: =IF($A6="","",$R6&"|"&$Q6) | T6: =IF($A6="","",$S6&"|"&$F6) | U6: =IF($A6="","",$R6&"("&$E6&")") | V6: =IF($A6="","",$F6&"|"&$U6&"|"&$D6) | W6: =IF($T6="","",IF($X6>N($X5),$X6,"")) | X6: =IF($T6="",N($X5),IF(MATCH($T6,$T$6:$T$10005,0)=ROW()-5,N($X5)+1,N($X5))) -> 0 | Z6: =IF($V6="","",IF($AA6>N($AA5),$AA6,"")) | AA6: =IF($V6="",N($AA5),IF(MATCH($V6,$V$6:$V$10005,0)=ROW()-5,N($AA5)+1,N($AA5))) -> 0
L7: =IF(OR($A7="",AND($J7="",$K7="")),"",ROUND(N($J7)-N($K7),2)) | M7: =IF(OR($A7="",AND($J7="",$K7="")),"",MIN($J7,$K7)) | N7: แถวที่กรอกไม่ครบ | O7: =SUMPRODUCT(--($A$6:$A$10005<>""),--((($B$6:$B$10005="")+($C$6:$C$10005="")+($D$6:$D$10005="")+($E$6:$E$10005="")+($F$6:$F$10005="")+($G$6:$G$10005="")+($M$6:$M$10005=""))>0)) -> 0 | Q7: =IF($A7="","",$D7&"("&SUBSTITUTE($E7," ","")&")") | R7: =IF($A7="","",$B7&" - "&$C7) | S7: =IF($A7="","",$R7&"|"&$Q7) | T7: =IF($A7="","",$S7&"|"&$F7) | U7: =IF($A7="","",$R7&"("&$E7&")") | V7: =IF($A7="","",$F7&"|"&$U7&"|"&$D7) | W7: =IF($T7="","",IF($X7>N($X6),$X7,"")) | X7: =IF($T7="",N($X6),IF(MATCH($T7,$T$6:$T$10005,0)=ROW()-5,N($X6)+1,N($X6))) -> 0 | Z7: =IF($V7="","",IF($AA7>N($AA6),$AA7,"")) | AA7: =IF($V7="",N($AA6),IF(MATCH($V7,$V$6:$V$10005,0)=ROW()-5,N($AA6)+1,N($AA6))) -> 0
L8: =IF(OR($A8="",AND($J8="",$K8="")),"",ROUND(N($J8)-N($K8),2)) | M8: =IF(OR($A8="",AND($J8="",$K8="")),"",MIN($J8,$K8)) | N8: จำนวนกลุ่ม หน้าสรุปเหมือง | O8: =N($X$10005) -> 0 | Q8: =IF($A8="","",$D8&"("&SUBSTITUTE($E8," ","")&")") | R8: =IF($A8="","",$B8&" - "&$C8) | S8: =IF($A8="","",$R8&"|"&$Q8) | T8: =IF($A8="","",$S8&"|"&$F8) | U8: =IF($A8="","",$R8&"("&$E8&")") | V8: =IF($A8="","",$F8&"|"&$U8&"|"&$D8) | W8: =IF($T8="","",IF($X8>N($X7),$X8,"")) | X8: =IF($T8="",N($X7),IF(MATCH($T8,$T$6:$T$10005,0)=ROW()-5,N($X7)+1,N($X7))) -> 0 | Z8: =IF($V8="","",IF($AA8>N($AA7),$AA8,"")) | AA8: =IF($V8="",N($AA7),IF(MATCH($V8,$V$6:$V$10005,0)=ROW()-5,N($AA7)+1,N($AA7))) -> 0
L9: =IF(OR($A9="",AND($J9="",$K9="")),"",ROUND(N($J9)-N($K9),2)) | M9: =IF(OR($A9="",AND($J9="",$K9="")),"",MIN($J9,$K9)) | N9: จำนวนกลุ่ม หน้าสรุปบัญชี | O9: =N($AA$10005) -> 0 | Q9: =IF($A9="","",$D9&"("&SUBSTITUTE($E9," ","")&")") | R9: =IF($A9="","",$B9&" - "&$C9) | S9: =IF($A9="","",$R9&"|"&$Q9) | T9: =IF($A9="","",$S9&"|"&$F9) | U9: =IF($A9="","",$R9&"("&$E9&")") | V9: =IF($A9="","",$F9&"|"&$U9&"|"&$D9) | W9: =IF($T9="","",IF($X9>N($X8),$X9,"")) | X9: =IF($T9="",N($X8),IF(MATCH($T9,$T$6:$T$10005,0)=ROW()-5,N($X8)+1,N($X8))) -> 0 | Z9: =IF($V9="","",IF($AA9>N($AA8),$AA9,"")) | AA9: =IF($V9="",N($AA8),IF(MATCH($V9,$V$6:$V$10005,0)=ROW()-5,N($AA8)+1,N($AA8))) -> 0
L10: =IF(OR($A10="",AND($J10="",$K10="")),"",ROUND(N($J10)-N($K10),2)) | M10: =IF(OR($A10="",AND($J10="",$K10="")),"",MIN($J10,$K10)) | N10: ชื่อที่ไม่อยู่ในรายการ (เช็คการวางทับ) | O10: =SUMPRODUCT(--($B$6:$B$10005<>""),--(COUNTIF(รายการมาตรฐาน!$B$2:$B$302,$B$6:$B$10005)=0))+SUMPRODUCT(--($C$6:$C$10005<>""),--(COUNTIF(รายการมาตรฐาน!$C$2:$C$302,$C$6:$C$10005)=0))+SUMPRODUCT(--($D$6:$D$10005<>""),--(COUNTIF(รายการมาตรฐาน!$D$2:$D$302,$D$6:$D$10005)=0))+SUMPRODUCT(--($E$6:$E$10005<>""),--(COUNTIF(รายการมาตรฐาน!$E$2:$E$302,$E$6:$E$10005)=0))+SUMPRODUCT(--($F$6:$F$10005<>""),--(COUNTIF(รายการมาตรฐาน!$F$2:$F$302,$F$6:$F$10005)=0))+SUMPRODUCT(--($G$6:$G$10005<>""),--(COUNTIF(รายการมาตรฐาน!$A$2:$A$302,$G$6:$G$10005)=0)) -> 0 | Q10: =IF($A10="","",$D10&"("&SUBSTITUTE($E10," ","")&")") | R10: =IF($A10="","",$B10&" - "&$C10) | S10: =IF($A10="","",$R10&"|"&$Q10) | T10: =IF($A10="","",$S10&"|"&$F10) | U10: =IF($A10="","",$R10&"("&$E10&")") | V10: =IF($A10="","",$F10&"|"&$U10&"|"&$D10) | W10: =IF($T10="","",IF($X10>N($X9),$X10,"")) | X10: =IF($T10="",N($X9),IF(MATCH($T10,$T$6:$T$10005,0)=ROW()-5,N($X9)+1,N($X9))) -> 0 | Z10: =IF($V10="","",IF($AA10>N($AA9),$AA10,"")) | AA10: =IF($V10="",N($AA9),IF(MATCH($V10,$V$6:$V$10005,0)=ROW()-5,N($AA9)+1,N($AA9))) -> 0
L11: =IF(OR($A11="",AND($J11="",$K11="")),"",ROUND(N($J11)-N($K11),2)) | M11: =IF(OR($A11="",AND($J11="",$K11="")),"",MIN($J11,$K11)) | N11: เตือน | O11: =IF($O$10>0,"*** มีชื่อที่ไม่อยู่ในรายการ — น่าจะเกิดจากการวางทับ ***",IF(OR($O$8>400,$O$9>400),"*** กลุ่มเกิน 400 — แยกไฟล์ ***",IF($O$7>0,"*** มีแถวกรอกไม่ครบ ***","ปกติ"))) -> ปกติ | Q11: =IF($A11="","",$D11&"("&SUBSTITUTE($E11," ","")&")") | R11: =IF($A11="","",$B11&" - "&$C11) | S11: =IF($A11="","",$R11&"|"&$Q11) | T11: =IF($A11="","",$S11&"|"&$F11) | U11: =IF($A11="","",$R11&"("&$E11&")") | V11: =IF($A11="","",$F11&"|"&$U11&"|"&$D11) | W11: =IF($T11="","",IF($X11>N($X10),$X11,"")) | X11: =IF($T11="",N($X10),IF(MATCH($T11,$T$6:$T$10005,0)=ROW()-5,N($X10)+1,N($X10))) -> 0 | Z11: =IF($V11="","",IF($AA11>N($AA10),$AA11,"")) | AA11: =IF($V11="",N($AA10),IF(MATCH($V11,$V$6:$V$10005,0)=ROW()-5,N($AA10)+1,N($AA10))) -> 0
L12: =IF(OR($A12="",AND($J12="",$K12="")),"",ROUND(N($J12)-N($K12),2)) | M12: =IF(OR($A12="",AND($J12="",$K12="")),"",MIN($J12,$K12)) | Q12: =IF($A12="","",$D12&"("&SUBSTITUTE($E12," ","")&")") | R12: =IF($A12="","",$B12&" - "&$C12) | S12: =IF($A12="","",$R12&"|"&$Q12) | T12: =IF($A12="","",$S12&"|"&$F12) | U12: =IF($A12="","",$R12&"("&$E12&")") | V12: =IF($A12="","",$F12&"|"&$U12&"|"&$D12) | W12: =IF($T12="","",IF($X12>N($X11),$X12,"")) | X12: =IF($T12="",N($X11),IF(MATCH($T12,$T$6:$T$10005,0)=ROW()-5,N($X11)+1,N($X11))) -> 0 | Z12: =IF($V12="","",IF($AA12>N($AA11),$AA12,"")) | AA12: =IF($V12="",N($AA11),IF(MATCH($V12,$V$6:$V$10005,0)=ROW()-5,N($AA11)+1,N($AA11))) -> 0
L13: =IF(OR($A13="",AND($J13="",$K13="")),"",ROUND(N($J13)-N($K13),2)) | M13: =IF(OR($A13="",AND($J13="",$K13="")),"",MIN($J13,$K13)) | Q13: =IF($A13="","",$D13&"("&SUBSTITUTE($E13," ","")&")") | R13: =IF($A13="","",$B13&" - "&$C13) | S13: =IF($A13="","",$R13&"|"&$Q13) | T13: =IF($A13="","",$S13&"|"&$F13) | U13: =IF($A13="","",$R13&"("&$E13&")") | V13: =IF($A13="","",$F13&"|"&$U13&"|"&$D13) | W13: =IF($T13="","",IF($X13>N($X12),$X13,"")) | X13: =IF($T13="",N($X12),IF(MATCH($T13,$T$6:$T$10005,0)=ROW()-5,N($X12)+1,N($X12))) -> 0 | Z13: =IF($V13="","",IF($AA13>N($AA12),$AA13,"")) | AA13: =IF($V13="",N($AA12),IF(MATCH($V13,$V$6:$V$10005,0)=ROW()-5,N($AA12)+1,N($AA12))) -> 0
L14: =IF(OR($A14="",AND($J14="",$K14="")),"",ROUND(N($J14)-N($K14),2)) | M14: =IF(OR($A14="",AND($J14="",$K14="")),"",MIN($J14,$K14)) | Q14: =IF($A14="","",$D14&"("&SUBSTITUTE($E14," ","")&")") | R14: =IF($A14="","",$B14&" - "&$C14) | S14: =IF($A14="","",$R14&"|"&$Q14) | T14: =IF($A14="","",$S14&"|"&$F14) | U14: =IF($A14="","",$R14&"("&$E14&")") | V14: =IF($A14="","",$F14&"|"&$U14&"|"&$D14) | W14: =IF($T14="","",IF($X14>N($X13),$X14,"")) | X14: =IF($T14="",N($X13),IF(MATCH($T14,$T$6:$T$10005,0)=ROW()-5,N($X13)+1,N($X13))) -> 0 | Z14: =IF($V14="","",IF($AA14>N($AA13),$AA14,"")) | AA14: =IF($V14="",N($AA13),IF(MATCH($V14,$V$6:$V$10005,0)=ROW()-5,N($AA13)+1,N($AA13))) -> 0
L15: =IF(OR($A15="",AND($J15="",$K15="")),"",ROUND(N($J15)-N($K15),2)) | M15: =IF(OR($A15="",AND($J15="",$K15="")),"",MIN($J15,$K15)) | Q15: =IF($A15="","",$D15&"("&SUBSTITUTE($E15," ","")&")") | R15: =IF($A15="","",$B15&" - "&$C15) | S15: =IF($A15="","",$R15&"|"&$Q15) | T15: =IF($A15="","",$S15&"|"&$F15) | U15: =IF($A15="","",$R15&"("&$E15&")") | V15: =IF($A15="","",$F15&"|"&$U15&"|"&$D15) | W15: =IF($T15="","",IF($X15>N($X14),$X15,"")) | X15: =IF($T15="",N($X14),IF(MATCH($T15,$T$6:$T$10005,0)=ROW()-5,N($X14)+1,N($X14))) -> 0 | Z15: =IF($V15="","",IF($AA15>N($AA14),$AA15,"")) | AA15: =IF($V15="",N($AA14),IF(MATCH($V15,$V$6:$V$10005,0)=ROW()-5,N($AA14)+1,N($AA14))) -> 0
L16: =IF(OR($A16="",AND($J16="",$K16="")),"",ROUND(N($J16)-N($K16),2)) | M16: =IF(OR($A16="",AND($J16="",$K16="")),"",MIN($J16,$K16)) | Q16: =IF($A16="","",$D16&"("&SUBSTITUTE($E16," ","")&")") | R16: =IF($A16="","",$B16&" - "&$C16) | S16: =IF($A16="","",$R16&"|"&$Q16) | T16: =IF($A16="","",$S16&"|"&$F16) | U16: =IF($A16="","",$R16&"("&$E16&")") | V16: =IF($A16="","",$F16&"|"&$U16&"|"&$D16) | W16: =IF($T16="","",IF($X16>N($X15),$X16,"")) | X16: =IF($T16="",N($X15),IF(MATCH($T16,$T$6:$T$10005,0)=ROW()-5,N($X15)+1,N($X15))) -> 0 | Z16: =IF($V16="","",IF($AA16>N($AA15),$AA16,"")) | AA16: =IF($V16="",N($AA15),IF(MATCH($V16,$V$6:$V$10005,0)=ROW()-5,N($AA15)+1,N($AA15))) -> 0
L17: =IF(OR($A17="",AND($J17="",$K17="")),"",ROUND(N($J17)-N($K17),2)) | M17: =IF(OR($A17="",AND($J17="",$K17="")),"",MIN($J17,$K17)) | Q17: =IF($A17="","",$D17&"("&SUBSTITUTE($E17," ","")&")") | R17: =IF($A17="","",$B17&" - "&$C17) | S17: =IF($A17="","",$R17&"|"&$Q17) | T17: =IF($A17="","",$S17&"|"&$F17) | U17: =IF($A17="","",$R17&"("&$E17&")") | V17: =IF($A17="","",$F17&"|"&$U17&"|"&$D17) | W17: =IF($T17="","",IF($X17>N($X16),$X17,"")) | X17: =IF($T17="",N($X16),IF(MATCH($T17,$T$6:$T$10005,0)=ROW()-5,N($X16)+1,N($X16))) -> 0 | Z17: =IF($V17="","",IF($AA17>N($AA16),$AA17,"")) | AA17: =IF($V17="",N($AA16),IF(MATCH($V17,$V$6:$V$10005,0)=ROW()-5,N($AA16)+1,N($AA16))) -> 0
L18: =IF(OR($A18="",AND($J18="",$K18="")),"",ROUND(N($J18)-N($K18),2)) | M18: =IF(OR($A18="",AND($J18="",$K18="")),"",MIN($J18,$K18)) | Q18: =IF($A18="","",$D18&"("&SUBSTITUTE($E18," ","")&")") | R18: =IF($A18="","",$B18&" - "&$C18) | S18: =IF($A18="","",$R18&"|"&$Q18) | T18: =IF($A18="","",$S18&"|"&$F18) | U18: =IF($A18="","",$R18&"("&$E18&")") | V18: =IF($A18="","",$F18&"|"&$U18&"|"&$D18) | W18: =IF($T18="","",IF($X18>N($X17),$X18,"")) | X18: =IF($T18="",N($X17),IF(MATCH($T18,$T$6:$T$10005,0)=ROW()-5,N($X17)+1,N($X17))) -> 0 | Z18: =IF($V18="","",IF($AA18>N($AA17),$AA18,"")) | AA18: =IF($V18="",N($AA17),IF(MATCH($V18,$V$6:$V$10005,0)=ROW()-5,N($AA17)+1,N($AA17))) -> 0
L19: =IF(OR($A19="",AND($J19="",$K19="")),"",ROUND(N($J19)-N($K19),2)) | M19: =IF(OR($A19="",AND($J19="",$K19="")),"",MIN($J19,$K19)) | Q19: =IF($A19="","",$D19&"("&SUBSTITUTE($E19," ","")&")") | R19: =IF($A19="","",$B19&" - "&$C19) | S19: =IF($A19="","",$R19&"|"&$Q19) | T19: =IF($A19="","",$S19&"|"&$F19) | U19: =IF($A19="","",$R19&"("&$E19&")") | V19: =IF($A19="","",$F19&"|"&$U19&"|"&$D19) | W19: =IF($T19="","",IF($X19>N($X18),$X19,"")) | X19: =IF($T19="",N($X18),IF(MATCH($T19,$T$6:$T$10005,0)=ROW()-5,N($X18)+1,N($X18))) -> 0 | Z19: =IF($V19="","",IF($AA19>N($AA18),$AA19,"")) | AA19: =IF($V19="",N($AA18),IF(MATCH($V19,$V$6:$V$10005,0)=ROW()-5,N($AA18)+1,N($AA18))) -> 0
L20: =IF(OR($A20="",AND($J20="",$K20="")),"",ROUND(N($J20)-N($K20),2)) | M20: =IF(OR($A20="",AND($J20="",$K20="")),"",MIN($J20,$K20)) | Q20: =IF($A20="","",$D20&"("&SUBSTITUTE($E20," ","")&")") | R20: =IF($A20="","",$B20&" - "&$C20) | S20: =IF($A20="","",$R20&"|"&$Q20) | T20: =IF($A20="","",$S20&"|"&$F20) | U20: =IF($A20="","",$R20&"("&$E20&")") | V20: =IF($A20="","",$F20&"|"&$U20&"|"&$D20) | W20: =IF($T20="","",IF($X20>N($X19),$X20,"")) | X20: =IF($T20="",N($X19),IF(MATCH($T20,$T$6:$T$10005,0)=ROW()-5,N($X19)+1,N($X19))) -> 0 | Z20: =IF($V20="","",IF($AA20>N($AA19),$AA20,"")) | AA20: =IF($V20="",N($AA19),IF(MATCH($V20,$V$6:$V$10005,0)=ROW()-5,N($AA19)+1,N($AA19))) -> 0
L21: =IF(OR($A21="",AND($J21="",$K21="")),"",ROUND(N($J21)-N($K21),2)) | M21: =IF(OR($A21="",AND($J21="",$K21="")),"",MIN($J21,$K21)) | Q21: =IF($A21="","",$D21&"("&SUBSTITUTE($E21," ","")&")") | R21: =IF($A21="","",$B21&" - "&$C21) | S21: =IF($A21="","",$R21&"|"&$Q21) | T21: =IF($A21="","",$S21&"|"&$F21) | U21: =IF($A21="","",$R21&"("&$E21&")") | V21: =IF($A21="","",$F21&"|"&$U21&"|"&$D21) | W21: =IF($T21="","",IF($X21>N($X20),$X21,"")) | X21: =IF($T21="",N($X20),IF(MATCH($T21,$T$6:$T$10005,0)=ROW()-5,N($X20)+1,N($X20))) -> 0 | Z21: =IF($V21="","",IF($AA21>N($AA20),$AA21,"")) | AA21: =IF($V21="",N($AA20),IF(MATCH($V21,$V$6:$V$10005,0)=ROW()-5,N($AA20)+1,N($AA20))) -> 0
L22: =IF(OR($A22="",AND($J22="",$K22="")),"",ROUND(N($J22)-N($K22),2)) | M22: =IF(OR($A22="",AND($J22="",$K22="")),"",MIN($J22,$K22)) | Q22: =IF($A22="","",$D22&"("&SUBSTITUTE($E22," ","")&")") | R22: =IF($A22="","",$B22&" - "&$C22) | S22: =IF($A22="","",$R22&"|"&$Q22) | T22: =IF($A22="","",$S22&"|"&$F22) | U22: =IF($A22="","",$R22&"("&$E22&")") | V22: =IF($A22="","",$F22&"|"&$U22&"|"&$D22) | W22: =IF($T22="","",IF($X22>N($X21),$X22,"")) | X22: =IF($T22="",N($X21),IF(MATCH($T22,$T$6:$T$10005,0)=ROW()-5,N($X21)+1,N($X21))) -> 0 | Z22: =IF($V22="","",IF($AA22>N($AA21),$AA22,"")) | AA22: =IF($V22="",N($AA21),IF(MATCH($V22,$V$6:$V$10005,0)=ROW()-5,N($AA21)+1,N($AA21))) -> 0
L23: =IF(OR($A23="",AND($J23="",$K23="")),"",ROUND(N($J23)-N($K23),2)) | M23: =IF(OR($A23="",AND($J23="",$K23="")),"",MIN($J23,$K23)) | Q23: =IF($A23="","",$D23&"("&SUBSTITUTE($E23," ","")&")") | R23: =IF($A23="","",$B23&" - "&$C23) | S23: =IF($A23="","",$R23&"|"&$Q23) | T23: =IF($A23="","",$S23&"|"&$F23) | U23: =IF($A23="","",$R23&"("&$E23&")") | V23: =IF($A23="","",$F23&"|"&$U23&"|"&$D23) | W23: =IF($T23="","",IF($X23>N($X22),$X23,"")) | X23: =IF($T23="",N($X22),IF(MATCH($T23,$T$6:$T$10005,0)=ROW()-5,N($X22)+1,N($X22))) -> 0 | Z23: =IF($V23="","",IF($AA23>N($AA22),$AA23,"")) | AA23: =IF($V23="",N($AA22),IF(MATCH($V23,$V$6:$V$10005,0)=ROW()-5,N($AA22)+1,N($AA22))) -> 0
... L10004: =IF(OR($A10004="",AND($J10004="",$K10004="")),"",ROUND(N($J10004)-N($K10004),2)) | M10004: =IF(OR($A10004="",AND($J10004="",$K10004="")),"",MIN($J10004,$K10004)) | Q10004: =IF($A10004="","",$D10004&"("&SUBSTITUTE($E10004," ","")&")") | R10004: =IF($A10004="","",$B10004&" - "&$C10004) | S10004: =IF($A10004="","",$R10004&"|"&$Q10004) | T10004: =IF($A10004="","",$S10004&"|"&$F10004) | U10004: =IF($A10004="","",$R10004&"("&$E10004&")") | V10004: =IF($A10004="","",$F10004&"|"&$U10004&"|"&$D10004) | W10004: =IF($T10004="","",IF($X10004>N($X10003),$X10004,"")) | X10004: =IF($T10004="",N($X10003),IF(MATCH($T10004,$T$6:$T$10005,0)=ROW()-5,N($X10003)+1,N($X10003))) -> 0 | Z10004: =IF($V10004="","",IF($AA10004>N($AA10003),$AA10004,"")) | AA10004: =IF($V10004="",N($AA10003),IF(MATCH($V10004,$V$6:$V$10005,0)=ROW()-5,N($AA10003)+1,N($AA10003))) -> 0
L10005: =IF(OR($A10005="",AND($J10005="",$K10005="")),"",ROUND(N($J10005)-N($K10005),2)) | M10005: =IF(OR($A10005="",AND($J10005="",$K10005="")),"",MIN($J10005,$K10005)) | Q10005: =IF($A10005="","",$D10005&"("&SUBSTITUTE($E10005," ","")&")") | R10005: =IF($A10005="","",$B10005&" - "&$C10005) | S10005: =IF($A10005="","",$R10005&"|"&$Q10005) | T10005: =IF($A10005="","",$S10005&"|"&$F10005) | U10005: =IF($A10005="","",$R10005&"("&$E10005&")") | V10005: =IF($A10005="","",$F10005&"|"&$U10005&"|"&$D10005) | W10005: =IF($T10005="","",IF($X10005>N($X6004),$X10005,"")) | X10005: =IF($T10005="",N($X6004),IF(MATCH($T10005,$T$6:$T$10005,0)=ROW()-5,N($X6004)+1,N($X6004))) -> 0 | Z10005: =IF($V10005="","",IF($AA10005>N($AA6004),$AA10005,"")) | AA10005: =IF($V10005="",N($AA6004),IF(MATCH($V10005,$V$6:$V$10005,0)=ROW()-5,N($AA6004)+1,N($AA6004))) -> 0

Sheet oil
A1: ="ค่าใช้จ่ายของทีมรถร่วม ประจำเดือน "&บันทึกรายเที่ยว!$B$3 -> ค่าใช้จ่ายของทีมรถร่วม ประจำเดือน กรกฎาคม 2569 | AH1: ▍ ช่องตรวจสอบ (ไม่ติดไปเวลาพิมพ์)
A2: ลำดับที่ | B2: อ้างถึงหนังสือที่ | C2: (หนังสือที่ 1) | F2: (หนังสือที่ 2) | I2: (หนังสือที่ 3) | L2: (หนังสือที่ 4) | O2: (หนังสือที่ 5) | R2: (หนังสือที่ 6) | U2: (หนังสือที่ 7) | X2: (หนังสือที่ 8) | AA2: หักอื่น | AB2: หักอื่น | AC2: หักอื่น | AD2: หักอื่น | AE2: รวมทั้งสิ้น | AH2: จำนวนทีมที่กรอก | AI2: =COUNTA($B$4:$B$63) -> 0
B3: รถร่วม | C3: จำนวน (ลิตร) | D3: ราคา/ลิตร | E3: จำนวนเงิน | F3: จำนวน (ลิตร) | G3: ราคา/ลิตร | H3: จำนวนเงิน | I3: จำนวน (ลิตร) | J3: ราคา/ลิตร | K3: จำนวนเงิน | L3: จำนวน (ลิตร) | M3: ราคา/ลิตร | N3: จำนวนเงิน | O3: จำนวน (ลิตร) | P3: ราคา/ลิตร | Q3: จำนวนเงิน | R3: จำนวน (ลิตร) | S3: ราคา/ลิตร | T3: จำนวนเงิน | U3: จำนวน (ลิตร) | V3: ราคา/ลิตร | W3: จำนวนเงิน | X3: จำนวน (ลิตร) | Y3: ราคา/ลิตร | Z3: จำนวนเงิน | AA3: (รายการที่ 1) | AB3: (รายการที่ 2) | AC3: (รายการที่ 3) | AD3: (รายการที่ 4) | AH3: รวมค่าหักทั้งสิ้น | AI3: =ROUND(SUM($AE$4:$AE$63),2) -> 0
A4: =IF($B4="","",COUNTA($B$4:$B4)) | AE4: =IF($B4="","",ROUND(N($E4)+N($H4)+N($K4)+N($N4)+N($Q4)+N($T4)+N($W4)+N($Z4)+N($AA4)+N($AB4)+N($AC4)+N($AD4),2)) | AF4: =IF($B4="",0,IF(AND($C4<>"",$D4<>"",$E4<>"",ABS($C4*$D4-$E4)>1),1,0)+IF(AND($F4<>"",$G4<>"",$H4<>"",ABS($F4*$G4-$H4)>1),1,0)+IF(AND($I4<>"",$J4<>"",$K4<>"",ABS($I4*$J4-$K4)>1),1,0)+IF(AND($L4<>"",$M4<>"",$N4<>"",ABS($L4*$M4-$N4)>1),1,0)+IF(AND($O4<>"",$P4<>"",$Q4<>"",ABS($O4*$P4-$Q4)>1),1,0)+IF(AND($R4<>"",$S4<>"",$T4<>"",ABS($R4*$S4-$T4)>1),1,0)+IF(AND($U4<>"",$V4<>"",$W4<>"",ABS($U4*$V4-$W4)>1),1,0)+IF(AND($X4<>"",$Y4<>"",$Z4<>"",ABS($X4*$Y4-$Z4)>1),1,0)) -> 0 | AH4: *** ทีมที่ไม่มีในสรุปจ่ายรถร่วม *** | AI4: =SUMPRODUCT(--($B$4:$B$63<>""),--(COUNTIF(สรุปจ่ายรถร่วม!$AF$5:$AF$704,$B$4:$B$63)=0)) -> 0
A5: =IF($B5="","",COUNTA($B$4:$B5)) | AE5: =IF($B5="","",ROUND(N($E5)+N($H5)+N($K5)+N($N5)+N($Q5)+N($T5)+N($W5)+N($Z5)+N($AA5)+N($AB5)+N($AC5)+N($AD5),2)) | AF5: =IF($B5="",0,IF(AND($C5<>"",$D5<>"",$E5<>"",ABS($C5*$D5-$E5)>1),1,0)+IF(AND($F5<>"",$G5<>"",$H5<>"",ABS($F5*$G5-$H5)>1),1,0)+IF(AND($I5<>"",$J5<>"",$K5<>"",ABS($I5*$J5-$K5)>1),1,0)+IF(AND($L5<>"",$M5<>"",$N5<>"",ABS($L5*$M5-$N5)>1),1,0)+IF(AND($O5<>"",$P5<>"",$Q5<>"",ABS($O5*$P5-$Q5)>1),1,0)+IF(AND($R5<>"",$S5<>"",$T5<>"",ABS($R5*$S5-$T5)>1),1,0)+IF(AND($U5<>"",$V5<>"",$W5<>"",ABS($U5*$V5-$W5)>1),1,0)+IF(AND($X5<>"",$Y5<>"",$Z5<>"",ABS($X5*$Y5-$Z5)>1),1,0)) -> 0 | AH5: *** แถวที่ ลิตร x ราคา ไม่ตรงกับจำนวนเงิน *** | AI5: =SUM($AF$4:$AF$63) -> 0
A6: =IF($B6="","",COUNTA($B$4:$B6)) | AE6: =IF($B6="","",ROUND(N($E6)+N($H6)+N($K6)+N($N6)+N($Q6)+N($T6)+N($W6)+N($Z6)+N($AA6)+N($AB6)+N($AC6)+N($AD6),2)) | AF6: =IF($B6="",0,IF(AND($C6<>"",$D6<>"",$E6<>"",ABS($C6*$D6-$E6)>1),1,0)+IF(AND($F6<>"",$G6<>"",$H6<>"",ABS($F6*$G6-$H6)>1),1,0)+IF(AND($I6<>"",$J6<>"",$K6<>"",ABS($I6*$J6-$K6)>1),1,0)+IF(AND($L6<>"",$M6<>"",$N6<>"",ABS($L6*$M6-$N6)>1),1,0)+IF(AND($O6<>"",$P6<>"",$Q6<>"",ABS($O6*$P6-$Q6)>1),1,0)+IF(AND($R6<>"",$S6<>"",$T6<>"",ABS($R6*$S6-$T6)>1),1,0)+IF(AND($U6<>"",$V6<>"",$W6<>"",ABS($U6*$V6-$W6)>1),1,0)+IF(AND($X6<>"",$Y6<>"",$Z6<>"",ABS($X6*$Y6-$Z6)>1),1,0)) -> 0 | AH6: ยอดหักที่ลงจริงในสรุปจ่ายรถร่วม | AI6: =ROUND(SUMIF(สรุปจ่ายรถร่วม!$AD$5:$AD$704,"T",สรุปจ่ายรถร่วม!$M$5:$M$704),2) -> 0
A7: =IF($B7="","",COUNTA($B$4:$B7)) | AE7: =IF($B7="","",ROUND(N($E7)+N($H7)+N($K7)+N($N7)+N($Q7)+N($T7)+N($W7)+N($Z7)+N($AA7)+N($AB7)+N($AC7)+N($AD7),2)) | AF7: =IF($B7="",0,IF(AND($C7<>"",$D7<>"",$E7<>"",ABS($C7*$D7-$E7)>1),1,0)+IF(AND($F7<>"",$G7<>"",$H7<>"",ABS($F7*$G7-$H7)>1),1,0)+IF(AND($I7<>"",$J7<>"",$K7<>"",ABS($I7*$J7-$K7)>1),1,0)+IF(AND($L7<>"",$M7<>"",$N7<>"",ABS($L7*$M7-$N7)>1),1,0)+IF(AND($O7<>"",$P7<>"",$Q7<>"",ABS($O7*$P7-$Q7)>1),1,0)+IF(AND($R7<>"",$S7<>"",$T7<>"",ABS($R7*$S7-$T7)>1),1,0)+IF(AND($U7<>"",$V7<>"",$W7<>"",ABS($U7*$V7-$W7)>1),1,0)+IF(AND($X7<>"",$Y7<>"",$Z7<>"",ABS($X7*$Y7-$Z7)>1),1,0)) -> 0 | AH7: สรุป | AI7: =IF($AI$4>0,"*** มีทีมที่ยอดหักจะหายไป — แก้ชื่อทีมก่อน ***",IF(ROUND($AI$3,2)<>ROUND($AI$6,2),"*** ยอดหักไม่ตรงกับสรุปจ่ายรถร่วม ***",IF($AI$5>0,"มีแถวที่ ลิตร x ราคา ไม่ตรงกับยอดเงิน (ตรวจดู)","ปกติ"))) -> ปกติ
A8: =IF($B8="","",COUNTA($B$4:$B8)) | AE8: =IF($B8="","",ROUND(N($E8)+N($H8)+N($K8)+N($N8)+N($Q8)+N($T8)+N($W8)+N($Z8)+N($AA8)+N($AB8)+N($AC8)+N($AD8),2)) | AF8: =IF($B8="",0,IF(AND($C8<>"",$D8<>"",$E8<>"",ABS($C8*$D8-$E8)>1),1,0)+IF(AND($F8<>"",$G8<>"",$H8<>"",ABS($F8*$G8-$H8)>1),1,0)+IF(AND($I8<>"",$J8<>"",$K8<>"",ABS($I8*$J8-$K8)>1),1,0)+IF(AND($L8<>"",$M8<>"",$N8<>"",ABS($L8*$M8-$N8)>1),1,0)+IF(AND($O8<>"",$P8<>"",$Q8<>"",ABS($O8*$P8-$Q8)>1),1,0)+IF(AND($R8<>"",$S8<>"",$T8<>"",ABS($R8*$S8-$T8)>1),1,0)+IF(AND($U8<>"",$V8<>"",$W8<>"",ABS($U8*$V8-$W8)>1),1,0)+IF(AND($X8<>"",$Y8<>"",$Z8<>"",ABS($X8*$Y8-$Z8)>1),1,0)) -> 0
A9: =IF($B9="","",COUNTA($B$4:$B9)) | AE9: =IF($B9="","",ROUND(N($E9)+N($H9)+N($K9)+N($N9)+N($Q9)+N($T9)+N($W9)+N($Z9)+N($AA9)+N($AB9)+N($AC9)+N($AD9),2)) | AF9: =IF($B9="",0,IF(AND($C9<>"",$D9<>"",$E9<>"",ABS($C9*$D9-$E9)>1),1,0)+IF(AND($F9<>"",$G9<>"",$H9<>"",ABS($F9*$G9-$H9)>1),1,0)+IF(AND($I9<>"",$J9<>"",$K9<>"",ABS($I9*$J9-$K9)>1),1,0)+IF(AND($L9<>"",$M9<>"",$N9<>"",ABS($L9*$M9-$N9)>1),1,0)+IF(AND($O9<>"",$P9<>"",$Q9<>"",ABS($O9*$P9-$Q9)>1),1,0)+IF(AND($R9<>"",$S9<>"",$T9<>"",ABS($R9*$S9-$T9)>1),1,0)+IF(AND($U9<>"",$V9<>"",$W9<>"",ABS($U9*$V9-$W9)>1),1,0)+IF(AND($X9<>"",$Y9<>"",$Z9<>"",ABS($X9*$Y9-$Z9)>1),1,0)) -> 0 | AH9: หมายเหตุ: ชื่อหนังสือในแถวที่ 2 และชื่อรายการหักในแถวที่ 3 พิมพ์ทับได้ตามแต่ละนาม | บล็อกที่ไม่ใช้ปล่อยว่างไว้
A10: =IF($B10="","",COUNTA($B$4:$B10)) | AE10: =IF($B10="","",ROUND(N($E10)+N($H10)+N($K10)+N($N10)+N($Q10)+N($T10)+N($W10)+N($Z10)+N($AA10)+N($AB10)+N($AC10)+N($AD10),2)) | AF10: =IF($B10="",0,IF(AND($C10<>"",$D10<>"",$E10<>"",ABS($C10*$D10-$E10)>1),1,0)+IF(AND($F10<>"",$G10<>"",$H10<>"",ABS($F10*$G10-$H10)>1),1,0)+IF(AND($I10<>"",$J10<>"",$K10<>"",ABS($I10*$J10-$K10)>1),1,0)+IF(AND($L10<>"",$M10<>"",$N10<>"",ABS($L10*$M10-$N10)>1),1,0)+IF(AND($O10<>"",$P10<>"",$Q10<>"",ABS($O10*$P10-$Q10)>1),1,0)+IF(AND($R10<>"",$S10<>"",$T10<>"",ABS($R10*$S10-$T10)>1),1,0)+IF(AND($U10<>"",$V10<>"",$W10<>"",ABS($U10*$V10-$W10)>1),1,0)+IF(AND($X10<>"",$Y10<>"",$Z10<>"",ABS($X10*$Y10-$Z10)>1),1,0)) -> 0
A11: =IF($B11="","",COUNTA($B$4:$B11)) | AE11: =IF($B11="","",ROUND(N($E11)+N($H11)+N($K11)+N($N11)+N($Q11)+N($T11)+N($W11)+N($Z11)+N($AA11)+N($AB11)+N($AC11)+N($AD11),2)) | AF11: =IF($B11="",0,IF(AND($C11<>"",$D11<>"",$E11<>"",ABS($C11*$D11-$E11)>1),1,0)+IF(AND($F11<>"",$G11<>"",$H11<>"",ABS($F11*$G11-$H11)>1),1,0)+IF(AND($I11<>"",$J11<>"",$K11<>"",ABS($I11*$J11-$K11)>1),1,0)+IF(AND($L11<>"",$M11<>"",$N11<>"",ABS($L11*$M11-$N11)>1),1,0)+IF(AND($O11<>"",$P11<>"",$Q11<>"",ABS($O11*$P11-$Q11)>1),1,0)+IF(AND($R11<>"",$S11<>"",$T11<>"",ABS($R11*$S11-$T11)>1),1,0)+IF(AND($U11<>"",$V11<>"",$W11<>"",ABS($U11*$V11-$W11)>1),1,0)+IF(AND($X11<>"",$Y11<>"",$Z11<>"",ABS($X11*$Y11-$Z11)>1),1,0)) -> 0 | AH11: หน้านี้ ฝ่ายบัญชี เป็นผู้กรอก (ไม่ใช่เหมือง)
A12: =IF($B12="","",COUNTA($B$4:$B12)) | AE12: =IF($B12="","",ROUND(N($E12)+N($H12)+N($K12)+N($N12)+N($Q12)+N($T12)+N($W12)+N($Z12)+N($AA12)+N($AB12)+N($AC12)+N($AD12),2)) | AF12: =IF($B12="",0,IF(AND($C12<>"",$D12<>"",$E12<>"",ABS($C12*$D12-$E12)>1),1,0)+IF(AND($F12<>"",$G12<>"",$H12<>"",ABS($F12*$G12-$H12)>1),1,0)+IF(AND($I12<>"",$J12<>"",$K12<>"",ABS($I12*$J12-$K12)>1),1,0)+IF(AND($L12<>"",$M12<>"",$N12<>"",ABS($L12*$M12-$N12)>1),1,0)+IF(AND($O12<>"",$P12<>"",$Q12<>"",ABS($O12*$P12-$Q12)>1),1,0)+IF(AND($R12<>"",$S12<>"",$T12<>"",ABS($R12*$S12-$T12)>1),1,0)+IF(AND($U12<>"",$V12<>"",$W12<>"",ABS($U12*$V12-$W12)>1),1,0)+IF(AND($X12<>"",$Y12<>"",$Z12<>"",ABS($X12*$Y12-$Z12)>1),1,0)) -> 0 | AH12: เหมืองส่งมาเฉพาะ บันทึกรายเที่ยว ที่ตรวจหน้าสรุปเหมืองแล้ว บัญชีมากรอก oil + อัตราค่าขนส่ง แล้วตรวจหน้าสรุปจ่ายรถร่วมอีกครั้ง
A13: =IF($B13="","",COUNTA($B$4:$B13)) | AE13: =IF($B13="","",ROUND(N($E13)+N($H13)+N($K13)+N($N13)+N($Q13)+N($T13)+N($W13)+N($Z13)+N($AA13)+N($AB13)+N($AC13)+N($AD13),2)) | AF13: =IF($B13="",0,IF(AND($C13<>"",$D13<>"",$E13<>"",ABS($C13*$D13-$E13)>1),1,0)+IF(AND($F13<>"",$G13<>"",$H13<>"",ABS($F13*$G13-$H13)>1),1,0)+IF(AND($I13<>"",$J13<>"",$K13<>"",ABS($I13*$J13-$K13)>1),1,0)+IF(AND($L13<>"",$M13<>"",$N13<>"",ABS($L13*$M13-$N13)>1),1,0)+IF(AND($O13<>"",$P13<>"",$Q13<>"",ABS($O13*$P13-$Q13)>1),1,0)+IF(AND($R13<>"",$S13<>"",$T13<>"",ABS($R13*$S13-$T13)>1),1,0)+IF(AND($U13<>"",$V13<>"",$W13<>"",ABS($U13*$V13-$W13)>1),1,0)+IF(AND($X13<>"",$Y13<>"",$Z13<>"",ABS($X13*$Y13-$Z13)>1),1,0)) -> 0
A14: =IF($B14="","",COUNTA($B$4:$B14)) | AE14: =IF($B14="","",ROUND(N($E14)+N($H14)+N($K14)+N($N14)+N($Q14)+N($T14)+N($W14)+N($Z14)+N($AA14)+N($AB14)+N($AC14)+N($AD14),2)) | AF14: =IF($B14="",0,IF(AND($C14<>"",$D14<>"",$E14<>"",ABS($C14*$D14-$E14)>1),1,0)+IF(AND($F14<>"",$G14<>"",$H14<>"",ABS($F14*$G14-$H14)>1),1,0)+IF(AND($I14<>"",$J14<>"",$K14<>"",ABS($I14*$J14-$K14)>1),1,0)+IF(AND($L14<>"",$M14<>"",$N14<>"",ABS($L14*$M14-$N14)>1),1,0)+IF(AND($O14<>"",$P14<>"",$Q14<>"",ABS($O14*$P14-$Q14)>1),1,0)+IF(AND($R14<>"",$S14<>"",$T14<>"",ABS($R14*$S14-$T14)>1),1,0)+IF(AND($U14<>"",$V14<>"",$W14<>"",ABS($U14*$V14-$W14)>1),1,0)+IF(AND($X14<>"",$Y14<>"",$Z14<>"",ABS($X14*$Y14-$Z14)>1),1,0)) -> 0
A15: =IF($B15="","",COUNTA($B$4:$B15)) | AE15: =IF($B15="","",ROUND(N($E15)+N($H15)+N($K15)+N($N15)+N($Q15)+N($T15)+N($W15)+N($Z15)+N($AA15)+N($AB15)+N($AC15)+N($AD15),2)) | AF15: =IF($B15="",0,IF(AND($C15<>"",$D15<>"",$E15<>"",ABS($C15*$D15-$E15)>1),1,0)+IF(AND($F15<>"",$G15<>"",$H15<>"",ABS($F15*$G15-$H15)>1),1,0)+IF(AND($I15<>"",$J15<>"",$K15<>"",ABS($I15*$J15-$K15)>1),1,0)+IF(AND($L15<>"",$M15<>"",$N15<>"",ABS($L15*$M15-$N15)>1),1,0)+IF(AND($O15<>"",$P15<>"",$Q15<>"",ABS($O15*$P15-$Q15)>1),1,0)+IF(AND($R15<>"",$S15<>"",$T15<>"",ABS($R15*$S15-$T15)>1),1,0)+IF(AND($U15<>"",$V15<>"",$W15<>"",ABS($U15*$V15-$W15)>1),1,0)+IF(AND($X15<>"",$Y15<>"",$Z15<>"",ABS($X15*$Y15-$Z15)>1),1,0)) -> 0
A16: =IF($B16="","",COUNTA($B$4:$B16)) | AE16: =IF($B16="","",ROUND(N($E16)+N($H16)+N($K16)+N($N16)+N($Q16)+N($T16)+N($W16)+N($Z16)+N($AA16)+N($AB16)+N($AC16)+N($AD16),2)) | AF16: =IF($B16="",0,IF(AND($C16<>"",$D16<>"",$E16<>"",ABS($C16*$D16-$E16)>1),1,0)+IF(AND($F16<>"",$G16<>"",$H16<>"",ABS($F16*$G16-$H16)>1),1,0)+IF(AND($I16<>"",$J16<>"",$K16<>"",ABS($I16*$J16-$K16)>1),1,0)+IF(AND($L16<>"",$M16<>"",$N16<>"",ABS($L16*$M16-$N16)>1),1,0)+IF(AND($O16<>"",$P16<>"",$Q16<>"",ABS($O16*$P16-$Q16)>1),1,0)+IF(AND($R16<>"",$S16<>"",$T16<>"",ABS($R16*$S16-$T16)>1),1,0)+IF(AND($U16<>"",$V16<>"",$W16<>"",ABS($U16*$V16-$W16)>1),1,0)+IF(AND($X16<>"",$Y16<>"",$Z16<>"",ABS($X16*$Y16-$Z16)>1),1,0)) -> 0
A17: =IF($B17="","",COUNTA($B$4:$B17)) | AE17: =IF($B17="","",ROUND(N($E17)+N($H17)+N($K17)+N($N17)+N($Q17)+N($T17)+N($W17)+N($Z17)+N($AA17)+N($AB17)+N($AC17)+N($AD17),2)) | AF17: =IF($B17="",0,IF(AND($C17<>"",$D17<>"",$E17<>"",ABS($C17*$D17-$E17)>1),1,0)+IF(AND($F17<>"",$G17<>"",$H17<>"",ABS($F17*$G17-$H17)>1),1,0)+IF(AND($I17<>"",$J17<>"",$K17<>"",ABS($I17*$J17-$K17)>1),1,0)+IF(AND($L17<>"",$M17<>"",$N17<>"",ABS($L17*$M17-$N17)>1),1,0)+IF(AND($O17<>"",$P17<>"",$Q17<>"",ABS($O17*$P17-$Q17)>1),1,0)+IF(AND($R17<>"",$S17<>"",$T17<>"",ABS($R17*$S17-$T17)>1),1,0)+IF(AND($U17<>"",$V17<>"",$W17<>"",ABS($U17*$V17-$W17)>1),1,0)+IF(AND($X17<>"",$Y17<>"",$Z17<>"",ABS($X17*$Y17-$Z17)>1),1,0)) -> 0
A18: =IF($B18="","",COUNTA($B$4:$B18)) | AE18: =IF($B18="","",ROUND(N($E18)+N($H18)+N($K18)+N($N18)+N($Q18)+N($T18)+N($W18)+N($Z18)+N($AA18)+N($AB18)+N($AC18)+N($AD18),2)) | AF18: =IF($B18="",0,IF(AND($C18<>"",$D18<>"",$E18<>"",ABS($C18*$D18-$E18)>1),1,0)+IF(AND($F18<>"",$G18<>"",$H18<>"",ABS($F18*$G18-$H18)>1),1,0)+IF(AND($I18<>"",$J18<>"",$K18<>"",ABS($I18*$J18-$K18)>1),1,0)+IF(AND($L18<>"",$M18<>"",$N18<>"",ABS($L18*$M18-$N18)>1),1,0)+IF(AND($O18<>"",$P18<>"",$Q18<>"",ABS($O18*$P18-$Q18)>1),1,0)+IF(AND($R18<>"",$S18<>"",$T18<>"",ABS($R18*$S18-$T18)>1),1,0)+IF(AND($U18<>"",$V18<>"",$W18<>"",ABS($U18*$V18-$W18)>1),1,0)+IF(AND($X18<>"",$Y18<>"",$Z18<>"",ABS($X18*$Y18-$Z18)>1),1,0)) -> 0
A19: =IF($B19="","",COUNTA($B$4:$B19)) | AE19: =IF($B19="","",ROUND(N($E19)+N($H19)+N($K19)+N($N19)+N($Q19)+N($T19)+N($W19)+N($Z19)+N($AA19)+N($AB19)+N($AC19)+N($AD19),2)) | AF19: =IF($B19="",0,IF(AND($C19<>"",$D19<>"",$E19<>"",ABS($C19*$D19-$E19)>1),1,0)+IF(AND($F19<>"",$G19<>"",$H19<>"",ABS($F19*$G19-$H19)>1),1,0)+IF(AND($I19<>"",$J19<>"",$K19<>"",ABS($I19*$J19-$K19)>1),1,0)+IF(AND($L19<>"",$M19<>"",$N19<>"",ABS($L19*$M19-$N19)>1),1,0)+IF(AND($O19<>"",$P19<>"",$Q19<>"",ABS($O19*$P19-$Q19)>1),1,0)+IF(AND($R19<>"",$S19<>"",$T19<>"",ABS($R19*$S19-$T19)>1),1,0)+IF(AND($U19<>"",$V19<>"",$W19<>"",ABS($U19*$V19-$W19)>1),1,0)+IF(AND($X19<>"",$Y19<>"",$Z19<>"",ABS($X19*$Y19-$Z19)>1),1,0)) -> 0
A20: =IF($B20="","",COUNTA($B$4:$B20)) | AE20: =IF($B20="","",ROUND(N($E20)+N($H20)+N($K20)+N($N20)+N($Q20)+N($T20)+N($W20)+N($Z20)+N($AA20)+N($AB20)+N($AC20)+N($AD20),2)) | AF20: =IF($B20="",0,IF(AND($C20<>"",$D20<>"",$E20<>"",ABS($C20*$D20-$E20)>1),1,0)+IF(AND($F20<>"",$G20<>"",$H20<>"",ABS($F20*$G20-$H20)>1),1,0)+IF(AND($I20<>"",$J20<>"",$K20<>"",ABS($I20*$J20-$K20)>1),1,0)+IF(AND($L20<>"",$M20<>"",$N20<>"",ABS($L20*$M20-$N20)>1),1,0)+IF(AND($O20<>"",$P20<>"",$Q20<>"",ABS($O20*$P20-$Q20)>1),1,0)+IF(AND($R20<>"",$S20<>"",$T20<>"",ABS($R20*$S20-$T20)>1),1,0)+IF(AND($U20<>"",$V20<>"",$W20<>"",ABS($U20*$V20-$W20)>1),1,0)+IF(AND($X20<>"",$Y20<>"",$Z20<>"",ABS($X20*$Y20-$Z20)>1),1,0)) -> 0
A21: =IF($B21="","",COUNTA($B$4:$B21)) | AE21: =IF($B21="","",ROUND(N($E21)+N($H21)+N($K21)+N($N21)+N($Q21)+N($T21)+N($W21)+N($Z21)+N($AA21)+N($AB21)+N($AC21)+N($AD21),2)) | AF21: =IF($B21="",0,IF(AND($C21<>"",$D21<>"",$E21<>"",ABS($C21*$D21-$E21)>1),1,0)+IF(AND($F21<>"",$G21<>"",$H21<>"",ABS($F21*$G21-$H21)>1),1,0)+IF(AND($I21<>"",$J21<>"",$K21<>"",ABS($I21*$J21-$K21)>1),1,0)+IF(AND($L21<>"",$M21<>"",$N21<>"",ABS($L21*$M21-$N21)>1),1,0)+IF(AND($O21<>"",$P21<>"",$Q21<>"",ABS($O21*$P21-$Q21)>1),1,0)+IF(AND($R21<>"",$S21<>"",$T21<>"",ABS($R21*$S21-$T21)>1),1,0)+IF(AND($U21<>"",$V21<>"",$W21<>"",ABS($U21*$V21-$W21)>1),1,0)+IF(AND($X21<>"",$Y21<>"",$Z21<>"",ABS($X21*$Y21-$Z21)>1),1,0)) -> 0
A22: =IF($B22="","",COUNTA($B$4:$B22)) | AE22: =IF($B22="","",ROUND(N($E22)+N($H22)+N($K22)+N($N22)+N($Q22)+N($T22)+N($W22)+N($Z22)+N($AA22)+N($AB22)+N($AC22)+N($AD22),2)) | AF22: =IF($B22="",0,IF(AND($C22<>"",$D22<>"",$E22<>"",ABS($C22*$D22-$E22)>1),1,0)+IF(AND($F22<>"",$G22<>"",$H22<>"",ABS($F22*$G22-$H22)>1),1,0)+IF(AND($I22<>"",$J22<>"",$K22<>"",ABS($I22*$J22-$K22)>1),1,0)+IF(AND($L22<>"",$M22<>"",$N22<>"",ABS($L22*$M22-$N22)>1),1,0)+IF(AND($O22<>"",$P22<>"",$Q22<>"",ABS($O22*$P22-$Q22)>1),1,0)+IF(AND($R22<>"",$S22<>"",$T22<>"",ABS($R22*$S22-$T22)>1),1,0)+IF(AND($U22<>"",$V22<>"",$W22<>"",ABS($U22*$V22-$W22)>1),1,0)+IF(AND($X22<>"",$Y22<>"",$Z22<>"",ABS($X22*$Y22-$Z22)>1),1,0)) -> 0
A23: =IF($B23="","",COUNTA($B$4:$B23)) | AE23: =IF($B23="","",ROUND(N($E23)+N($H23)+N($K23)+N($N23)+N($Q23)+N($T23)+N($W23)+N($Z23)+N($AA23)+N($AB23)+N($AC23)+N($AD23),2)) | AF23: =IF($B23="",0,IF(AND($C23<>"",$D23<>"",$E23<>"",ABS($C23*$D23-$E23)>1),1,0)+IF(AND($F23<>"",$G23<>"",$H23<>"",ABS($F23*$G23-$H23)>1),1,0)+IF(AND($I23<>"",$J23<>"",$K23<>"",ABS($I23*$J23-$K23)>1),1,0)+IF(AND($L23<>"",$M23<>"",$N23<>"",ABS($L23*$M23-$N23)>1),1,0)+IF(AND($O23<>"",$P23<>"",$Q23<>"",ABS($O23*$P23-$Q23)>1),1,0)+IF(AND($R23<>"",$S23<>"",$T23<>"",ABS($R23*$S23-$T23)>1),1,0)+IF(AND($U23<>"",$V23<>"",$W23<>"",ABS($U23*$V23-$W23)>1),1,0)+IF(AND($X23<>"",$Y23<>"",$Z23<>"",ABS($X23*$Y23-$Z23)>1),1,0)) -> 0
A24: =IF($B24="","",COUNTA($B$4:$B24)) | AE24: =IF($B24="","",ROUND(N($E24)+N($H24)+N($K24)+N($N24)+N($Q24)+N($T24)+N($W24)+N($Z24)+N($AA24)+N($AB24)+N($AC24)+N($AD24),2)) | AF24: =IF($B24="",0,IF(AND($C24<>"",$D24<>"",$E24<>"",ABS($C24*$D24-$E24)>1),1,0)+IF(AND($F24<>"",$G24<>"",$H24<>"",ABS($F24*$G24-$H24)>1),1,0)+IF(AND($I24<>"",$J24<>"",$K24<>"",ABS($I24*$J24-$K24)>1),1,0)+IF(AND($L24<>"",$M24<>"",$N24<>"",ABS($L24*$M24-$N24)>1),1,0)+IF(AND($O24<>"",$P24<>"",$Q24<>"",ABS($O24*$P24-$Q24)>1),1,0)+IF(AND($R24<>"",$S24<>"",$T24<>"",ABS($R24*$S24-$T24)>1),1,0)+IF(AND($U24<>"",$V24<>"",$W24<>"",ABS($U24*$V24-$W24)>1),1,0)+IF(AND($X24<>"",$Y24<>"",$Z24<>"",ABS($X24*$Y24-$Z24)>1),1,0)) -> 0
... A63: =IF($B63="","",COUNTA($B$4:$B63)) | AE63: =IF($B63="","",ROUND(N($E63)+N($H63)+N($K63)+N($N63)+N($Q63)+N($T63)+N($W63)+N($Z63)+N($AA63)+N($AB63)+N($AC63)+N($AD63),2)) | AF63: =IF($B63="",0,IF(AND($C63<>"",$D63<>"",$E63<>"",ABS($C63*$D63-$E63)>1),1,0)+IF(AND($F63<>"",$G63<>"",$H63<>"",ABS($F63*$G63-$H63)>1),1,0)+IF(AND($I63<>"",$J63<>"",$K63<>"",ABS($I63*$J63-$K63)>1),1,0)+IF(AND($L63<>"",$M63<>"",$N63<>"",ABS($L63*$M63-$N63)>1),1,0)+IF(AND($O63<>"",$P63<>"",$Q63<>"",ABS($O63*$P63-$Q63)>1),1,0)+IF(AND($R63<>"",$S63<>"",$T63<>"",ABS($R63*$S63-$T63)>1),1,0)+IF(AND($U63<>"",$V63<>"",$W63<>"",ABS($U63*$V63-$W63)>1),1,0)+IF(AND($X63<>"",$Y63<>"",$Z63<>"",ABS($X63*$Y63-$Z63)>1),1,0)) -> 0
B64: รวม | C64: =ROUND(SUM($C$4:$C$63),2) -> 0 | D64: =IF(OR(N($C$64)=0,SUMPRODUCT(--($E$4:$E$63<>""),--($C$4:$C$63=""))>0),"",ROUND($E$64/$C$64,4)) | E64: =ROUND(SUM($E$4:$E$63),2) -> 0 | F64: =ROUND(SUM($F$4:$F$63),2) -> 0 | G64: =IF(OR(N($F$64)=0,SUMPRODUCT(--($H$4:$H$63<>""),--($F$4:$F$63=""))>0),"",ROUND($H$64/$F$64,4)) | H64: =ROUND(SUM($H$4:$H$63),2) -> 0 | I64: =ROUND(SUM($I$4:$I$63),2) -> 0 | J64: =IF(OR(N($I$64)=0,SUMPRODUCT(--($K$4:$K$63<>""),--($I$4:$I$63=""))>0),"",ROUND($K$64/$I$64,4)) | K64: =ROUND(SUM($K$4:$K$63),2) -> 0 | L64: =ROUND(SUM($L$4:$L$63),2) -> 0 | M64: =IF(OR(N($L$64)=0,SUMPRODUCT(--($N$4:$N$63<>""),--($L$4:$L$63=""))>0),"",ROUND($N$64/$L$64,4)) | N64: =ROUND(SUM($N$4:$N$63),2) -> 0 | O64: =ROUND(SUM($O$4:$O$63),2) -> 0 | P64: =IF(OR(N($O$64)=0,SUMPRODUCT(--($Q$4:$Q$63<>""),--($O$4:$O$63=""))>0),"",ROUND($Q$64/$O$64,4)) | Q64: =ROUND(SUM($Q$4:$Q$63),2) -> 0 | R64: =ROUND(SUM($R$4:$R$63),2) -> 0 | S64: =IF(OR(N($R$64)=0,SUMPRODUCT(--($T$4:$T$63<>""),--($R$4:$R$63=""))>0),"",ROUND($T$64/$R$64,4)) | T64: =ROUND(SUM($T$4:$T$63),2) -> 0 | U64: =ROUND(SUM($U$4:$U$63),2) -> 0 | V64: =IF(OR(N($U$64)=0,SUMPRODUCT(--($W$4:$W$63<>""),--($U$4:$U$63=""))>0),"",ROUND($W$64/$U$64,4)) | W64: =ROUND(SUM($W$4:$W$63),2) -> 0 | X64: =ROUND(SUM($X$4:$X$63),2) -> 0 | Y64: =IF(OR(N($X$64)=0,SUMPRODUCT(--($Z$4:$Z$63<>""),--($X$4:$X$63=""))>0),"",ROUND($Z$64/$X$64,4)) | Z64: =ROUND(SUM($Z$4:$Z$63),2) -> 0 | AA64: =ROUND(SUM($AA$4:$AA$63),2) -> 0 | AB64: =ROUND(SUM($AB$4:$AB$63),2) -> 0 | AC64: =ROUND(SUM($AC$4:$AC$63),2) -> 0 | AD64: =ROUND(SUM($AD$4:$AD$63),2) -> 0 | AE64: =ROUND(SUM($AE$4:$AE$63),2) -> 0

Sheet สรุปเหมือง
A1: รายงานสรุปผลการขนส่งหิน (แบบเหมือง) | I1: ▍ ตัวกรองรายงาน — เลือกแล้วตารางจะแสดงเฉพาะที่เลือก | AD1: =COUNT($Q$8:$Q$407)+SUM($V$8:$V$407)+SUM($W$8:$W$407) -> 0
A2: ที่ | B2: =IF(บันทึกรายเที่ยว!$D$3="","",บันทึกรายเที่ยว!$D$3) | D2: ประจำเดือน | E2: =IF(บันทึกรายเที่ยว!$B$3="","",บันทึกรายเที่ยว!$B$3) -> กรกฎาคม 2569 | I2: ท่าปลายทาง
A3: เรื่อง | B3: รายงานการขนส่งหินจากเหมือง ไปท่าเรือ ประจำเดือน | I3: (ทั้งหมด)
A4: เรียน | I4: ชนิดแร่/หิน
A5: =IF($AD$1+7>200,"*** รายงานยาวเกินพื้นที่พิมพ์ที่ตั้งไว้ — ตั้ง Print Area ใหม่เป็น "&"A1:H"&(8-1+$AD$1+7)&" ก่อนพิมพ์ ***","") | I5: (ทั้งหมด)
A6: =" รายงานสรุปผลการขนส่ง ประจำเดือน "&บันทึกรายเที่ยว!$B$3&IF(AND($I$3="(ทั้งหมด)",$I$5="(ทั้งหมด)",$I$7="(ทั้งหมด)"),""," [กรองเฉพาะ:"&IF($I$3="(ทั้งหมด)",""," ปลายทาง="&$I$3)&IF($I$5="(ทั้งหมด)",""," ชนิด="&$I$5)&IF($I$7="(ทั้งหมด)",""," ทีม="&$I$7)&" ]") -> รายงานสรุปผลการขนส่ง ประจำเดือน กรกฎาคม 2569 | I6: ทีมรถร่วม
A7: ต้นทาง - ปลายทาง | B7: ชนิดหิน | C7: ขนส่ง (ทีม) | D7: เที่ยว | E7: นน.ต้นทาง (ตัน) | F7: นน.ปลายทาง (ตัน) | G7: นน.ส่วนต่าง (ตัน) | H7: นน.จ่ายค่าบรรทุก (ตัน) | I7: (ทั้งหมด)
A8: =IF($AB8="G","ผลรวมทั้งหมด",IF($AB8="R",INDEX($S$8:$S$407,$AA8),"")) -> ผลรวมทั้งหมด | B8: =IF($AB8="S",INDEX($Y$8:$Y$407,$AA8),"") | C8: =IF($AB8="D",INDEX($Z$8:$Z$407,$AA8),"") | D8: =IF($AB8="G",SUM($AE$8:$AE$407),IF(OR($AB8="",$AB8="R"),"",IF($AB8="D",INDEX($AE$8:$AE$407,$AA8),SUMIF($T$8:$T$407,INDEX($T$8:$T$407,$AA8),$AE$8:$AE$407)))) -> 0 | E8: =IF(1=$AD$1+3,"ขอแสดงความนับถือ",IF(1=$AD$1+6,"( )",IF(1=$AD$1+7,"เจ้าหน้าที่ขนส่ง",IF($AB8="G",SUM($AF$8:$AF$407),IF(OR($AB8="",$AB8="R"),"",IF($AB8="D",INDEX($AF$8:$AF$407,$AA8),SUMIF($T$8:$T$407,INDEX($T$8:$T$407,$AA8),$AF$8:$AF$407))))))) -> 0 | F8: =IF($AB8="G",SUM($AG$8:$AG$407),IF(OR($AB8="",$AB8="R"),"",IF($AB8="D",INDEX($AG$8:$AG$407,$AA8),SUMIF($T$8:$T$407,INDEX($T$8:$T$407,$AA8),$AG$8:$AG$407)))) -> 0 | G8: =IF(OR($AB8="",$AB8="R"),"",ROUND($E8-$F8,2)) -> 0 | H8: =IF($AB8="G",SUM($AH$8:$AH$407),IF(OR($AB8="",$AB8="R"),"",IF($AB8="D",INDEX($AH$8:$AH$407,$AA8),SUMIF($T$8:$T$407,INDEX($T$8:$T$407,$AA8),$AH$8:$AH$407)))) -> 0 | I8: ▍ ช่องตรวจสอบ (ไม่ติดไปเวลาพิมพ์) | J8: =IFERROR(MATCH(1,บันทึกรายเที่ยว!$W$6:$W$10005,0),"") | K8: =IF($J8="","",INDEX(บันทึกรายเที่ยว!$T$6:$T$10005,$J8)) | L8: =IF($J8="","",INDEX(บันทึกรายเที่ยว!$S$6:$S$10005,$J8)) | M8: =IF($J8="","",INDEX(บันทึกรายเที่ยว!$R$6:$R$10005,$J8)) | N8: =IF($J8="","",MATCH($M8,บันทึกรายเที่ยว!$R$6:$R$10005,0)) | O8: =IF($J8="","",MATCH($L8,บันทึกรายเที่ยว!$S$6:$S$10005,0)) | P8: =IF($J8="","",IF(AND(OR($I$3="(ทั้งหมด)",INDEX(บันทึกรายเที่ยว!$C$6:$C$10005,$J8)=$I$3),OR($I$5="(ทั้งหมด)",INDEX(บันทึกรายเที่ยว!$D$6:$D$10005,$J8)=$I$5),OR($I$7="(ทั้งหมด)",INDEX(บันทึกรายเที่ยว!$F$6:$F$10005,$J8)=$I$7)),$N8*10000000+$O8*1000+1,"")) | Q8: =IFERROR(MATCH(SMALL($P$8:$P$407,1),$P$8:$P$407,0),"") | R8: =IF($Q8="","",INDEX($J$8:$J$407,$Q8)) | S8: =IF($Q8="","",INDEX($M$8:$M$407,$Q8)) | T8: =IF($Q8="","",INDEX($L$8:$L$407,$Q8)) | U8: =IF($Q8="","",INDEX($K$8:$K$407,$Q8)) | V8: =IF($Q8="",0,1) -> 0 | W8: =IF($Q8="",0,1) -> 0 | X8: =IF($Q8="",99999,1) -> 99999 | Y8: =IF($Q8="","",INDEX(บันทึกรายเที่ยว!$Q$6:$Q$10005,$R8)) | Z8: =IF($Q8="","",INDEX(บันทึกรายเที่ยว!$F$6:$F$10005,$R8)) | AA8: =IFERROR(MATCH(1,$X$8:$X$407,1),"") | AB8: =IF(1=$AD$1+1,"G",IF($AA8="","",IF(INDEX($Q$8:$Q$407,$AA8)="","",IF(1>INDEX($X$8:$X$407,$AA8)+INDEX($V$8:$V$407,$AA8)+INDEX($W$8:$W$407,$AA8),"",IF(1=INDEX($X$8:$X$407,$AA8)+INDEX($V$8:$V$407,$AA8)+INDEX($W$8:$W$407,$AA8),"D",IF(AND(INDEX($W$8:$W$407,$AA8)=1,1=INDEX($X$8:$X$407,$AA8)+INDEX($V$8:$V$407,$AA8)),"S","R")))))) -> G | AC8: =IF(OR($AB8="",$AB8="G"),"",IF($AB8="D",INDEX($U$8:$U$407,$AA8),IF($AB8="S",INDEX($T$8:$T$407,$AA8)&"|*",INDEX($S$8:$S$407,$AA8)&"|*"))) | AE8: =IF($U8="",0,COUNTIF(บันทึกรายเที่ยว!$T$6:$T$10005,$U8)) -> 0 | AF8: =IF($U8="",0,ROUND(SUMIF(บันทึกรายเที่ยว!$T$6:$T$10005,$U8,บันทึกรายเที่ยว!$J$6:$J$10005),2)) -> 0 | AG8: =IF($U8="",0,ROUND(SUMIF(บันทึกรายเที่ยว!$T$6:$T$10005,$U8,บันทึกรายเที่ยว!$K$6:$K$10005),2)) -> 0 | AH8: =IF($U8="",0,ROUND(SUMIF(บันทึกรายเที่ยว!$T$6:$T$10005,$U8,บันทึกรายเที่ยว!$M$6:$M$10005),2)) -> 0
A9: =IF($AB9="G","ผลรวมทั้งหมด",IF($AB9="R",INDEX($S$8:$S$407,$AA9),"")) | B9: =IF($AB9="S",INDEX($Y$8:$Y$407,$AA9),"") | C9: =IF($AB9="D",INDEX($Z$8:$Z$407,$AA9),"") | D9: =IF($AB9="G",SUM($AE$8:$AE$407),IF(OR($AB9="",$AB9="R"),"",IF($AB9="D",INDEX($AE$8:$AE$407,$AA9),SUMIF($T$8:$T$407,INDEX($T$8:$T$407,$AA9),$AE$8:$AE$407)))) | E9: =IF(2=$AD$1+3,"ขอแสดงความนับถือ",IF(2=$AD$1+6,"( )",IF(2=$AD$1+7,"เจ้าหน้าที่ขนส่ง",IF($AB9="G",SUM($AF$8:$AF$407),IF(OR($AB9="",$AB9="R"),"",IF($AB9="D",INDEX($AF$8:$AF$407,$AA9),SUMIF($T$8:$T$407,INDEX($T$8:$T$407,$AA9),$AF$8:$AF$407))))))) | F9: =IF($AB9="G",SUM($AG$8:$AG$407),IF(OR($AB9="",$AB9="R"),"",IF($AB9="D",INDEX($AG$8:$AG$407,$AA9),SUMIF($T$8:$T$407,INDEX($T$8:$T$407,$AA9),$AG$8:$AG$407)))) | G9: =IF(OR($AB9="",$AB9="R"),"",ROUND($E9-$F9,2)) | H9: =IF($AB9="G",SUM($AH$8:$AH$407),IF(OR($AB9="",$AB9="R"),"",IF($AB9="D",INDEX($AH$8:$AH$407,$AA9),SUMIF($T$8:$T$407,INDEX($T$8:$T$407,$AA9),$AH$8:$AH$407)))) | I9: ตรวจสอบยอด | J9: =IFERROR(MATCH(2,บันทึกรายเที่ยว!$W$6:$W$10005,0),"") | K9: =IF($J9="","",INDEX(บันทึกรายเที่ยว!$T$6:$T$10005,$J9)) | L9: =IF($J9="","",INDEX(บันทึกรายเที่ยว!$S$6:$S$10005,$J9)) | M9: =IF($J9="","",INDEX(บันทึกรายเที่ยว!$R$6:$R$10005,$J9)) | N9: =IF($J9="","",MATCH($M9,บันทึกรายเที่ยว!$R$6:$R$10005,0)) | O9: =IF($J9="","",MATCH($L9,บันทึกรายเที่ยว!$S$6:$S$10005,0)) | P9: =IF($J9="","",IF(AND(OR($I$3="(ทั้งหมด)",INDEX(บันทึกรายเที่ยว!$C$6:$C$10005,$J9)=$I$3),OR($I$5="(ทั้งหมด)",INDEX(บันทึกรายเที่ยว!$D$6:$D$10005,$J9)=$I$5),OR($I$7="(ทั้งหมด)",INDEX(บันทึกรายเที่ยว!$F$6:$F$10005,$J9)=$I$7)),$N9*10000000+$O9*1000+2,"")) | Q9: =IFERROR(MATCH(SMALL($P$8:$P$407,2),$P$8:$P$407,0),"") | R9: =IF($Q9="","",INDEX($J$8:$J$407,$Q9)) | S9: =IF($Q9="","",INDEX($M$8:$M$407,$Q9)) | T9: =IF($Q9="","",INDEX($L$8:$L$407,$Q9)) | U9: =IF($Q9="","",INDEX($K$8:$K$407,$Q9)) | V9: =IF($Q9="",0,IF($S9<>$S8,1,0)) -> 0 | W9: =IF($Q9="",0,IF($T9<>$T8,1,0)) -> 0 | X9: =IF($Q9="",99999+2,$X8+1+$V8+$W8) -> 100001 | Y9: =IF($Q9="","",INDEX(บันทึกรายเที่ยว!$Q$6:$Q$10005,$R9)) | Z9: =IF($Q9="","",INDEX(บันทึกรายเที่ยว!$F$6:$F$10005,$R9)) | AA9: =IFERROR(MATCH(2,$X$8:$X$407,1),"") | AB9: =IF(2=$AD$1+1,"G",IF($AA9="","",IF(INDEX($Q$8:$Q$407,$AA9)="","",IF(2>INDEX($X$8:$X$407,$AA9)+INDEX($V$8:$V$407,$AA9)+INDEX($W$8:$W$407,$AA9),"",IF(2=INDEX($X$8:$X$407,$AA9)+INDEX($V$8:$V$407,$AA9)+INDEX($W$8:$W$407,$AA9),"D",IF(AND(INDEX($W$8:$W$407,$AA9)=1,2=INDEX($X$8:$X$407,$AA9)+INDEX($V$8:$V$407,$AA9)),"S","R")))))) | AC9: =IF(OR($AB9="",$AB9="G"),"",IF($AB9="D",INDEX($U$8:$U$407,$AA9),IF($AB9="S",INDEX($T$8:$T$407,$AA9)&"|*",INDEX($S$8:$S$407,$AA9)&"|*"))) | AE9: =IF($U9="",0,COUNTIF(บันทึกรายเที่ยว!$T$6:$T$10005,$U9)) -> 0 | AF9: =IF($U9="",0,ROUND(SUMIF(บันทึกรายเที่ยว!$T$6:$T$10005,$U9,บันทึกรายเที่ยว!$J$6:$J$10005),2)) -> 0 | AG9: =IF($U9="",0,ROUND(SUMIF(บันทึกรายเที่ยว!$T$6:$T$10005,$U9,บันทึกรายเที่ยว!$K$6:$K$10005),2)) -> 0 | AH9: =IF($U9="",0,ROUND(SUMIF(บันทึกรายเที่ยว!$T$6:$T$10005,$U9,บันทึกรายเที่ยว!$M$6:$M$10005),2)) -> 0
A10: =IF($AB10="G","ผลรวมทั้งหมด",IF($AB10="R",INDEX($S$8:$S$407,$AA10),"")) | B10: =IF($AB10="S",INDEX($Y$8:$Y$407,$AA10),"") | C10: =IF($AB10="D",INDEX($Z$8:$Z$407,$AA10),"") | D10: =IF($AB10="G",SUM($AE$8:$AE$407),IF(OR($AB10="",$AB10="R"),"",IF($AB10="D",INDEX($AE$8:$AE$407,$AA10),SUMIF($T$8:$T$407,INDEX($T$8:$T$407,$AA10),$AE$8:$AE$407)))) | E10: =IF(3=$AD$1+3,"ขอแสดงความนับถือ",IF(3=$AD$1+6,"( )",IF(3=$AD$1+7,"เจ้าหน้าที่ขนส่ง",IF($AB10="G",SUM($AF$8:$AF$407),IF(OR($AB10="",$AB10="R"),"",IF($AB10="D",INDEX($AF$8:$AF$407,$AA10),SUMIF($T$8:$T$407,INDEX($T$8:$T$407,$AA10),$AF$8:$AF$407))))))) -> ขอแสดงความนับถือ | F10: =IF($AB10="G",SUM($AG$8:$AG$407),IF(OR($AB10="",$AB10="R"),"",IF($AB10="D",INDEX($AG$8:$AG$407,$AA10),SUMIF($T$8:$T$407,INDEX($T$8:$T$407,$AA10),$AG$8:$AG$407)))) | G10: =IF(OR($AB10="",$AB10="R"),"",ROUND($E10-$F10,2)) | H10: =IF($AB10="G",SUM($AH$8:$AH$407),IF(OR($AB10="",$AB10="R"),"",IF($AB10="D",INDEX($AH$8:$AH$407,$AA10),SUMIF($T$8:$T$407,INDEX($T$8:$T$407,$AA10),$AH$8:$AH$407)))) | I10: =IF(AND($I$3="(ทั้งหมด)",$I$5="(ทั้งหมด)",$I$7="(ทั้งหมด)"),IF(ROUND(SUM($AH$8:$AH$407),2)=ROUND(SUM(บันทึกรายเที่ยว!$M$6:$M$10005),2),"ยอดตรงกับรายเที่ยว","*** ยอดไม่ตรง ***"),"กำลังกรองอยู่ — ยอดเป็นเฉพาะที่กรอง") -> ยอดตรงกับรายเที่ยว | J10: =IFERROR(MATCH(3,บันทึกรายเที่ยว!$W$6:$W$10005,0),"") | K10: =IF($J10="","",INDEX(บันทึกรายเที่ยว!$T$6:$T$10005,$J10)) | L10: =IF($J10="","",INDEX(บันทึกรายเที่ยว!$S$6:$S$10005,$J10)) | M10: =IF($J10="","",INDEX(บันทึกรายเที่ยว!$R$6:$R$10005,$J10)) | N10: =IF($J10="","",MATCH($M10,บันทึกรายเที่ยว!$R$6:$R$10005,0)) | O10: =IF($J10="","",MATCH($L10,บันทึกรายเที่ยว!$S$6:$S$10005,0)) | P10: =IF($J10="","",IF(AND(OR($I$3="(ทั้งหมด)",INDEX(บันทึกรายเที่ยว!$C$6:$C$10005,$J10)=$I$3),OR($I$5="(ทั้งหมด)",INDEX(บันทึกรายเที่ยว!$D$6:$D$10005,$J10)=$I$5),OR($I$7="(ทั้งหมด)",INDEX(บันทึกรายเที่ยว!$F$6:$F$10005,$J10)=$I$7)),$N10*10000000+$O10*1000+3,"")) | Q10: =IFERROR(MATCH(SMALL($P$8:$P$407,3),$P$8:$P$407,0),"") | R10: =IF($Q10="","",INDEX($J$8:$J$407,$Q10)) | S10: =IF($Q10="","",INDEX($M$8:$M$407,$Q10)) | T10: =IF($Q10="","",INDEX($L$8:$L$407,$Q10)) | U10: =IF($Q10="","",INDEX($K$8:$K$407,$Q10)) | V10: =IF($Q10="",0,IF($S10<>$S9,1,0)) -> 0 | W10: =IF($Q10="",0,IF($T10<>$T9,1,0)) -> 0 | X10: =IF($Q10="",99999+3,$X9+1+$V9+$W9) -> 100002 | Y10: =IF($Q10="","",INDEX(บันทึกรายเที่ยว!$Q$6:$Q$10005,$R10)) | Z10: =IF($Q10="","",INDEX(บันทึกรายเที่ยว!$F$6:$F$10005,$R10)) | AA10: =IFERROR(MATCH(3,$X$8:$X$407,1),"") | AB10: =IF(3=$AD$1+1,"G",IF($AA10="","",IF(INDEX($Q$8:$Q$407,$AA10)="","",IF(3>INDEX($X$8:$X$407,$AA10)+INDEX($V$8:$V$407,$AA10)+INDEX($W$8:$W$407,$AA10),"",IF(3=INDEX($X$8:$X$407,$AA10)+INDEX($V$8:$V$407,$AA10)+INDEX($W$8:$W$407,$AA10),"D",IF(AND(INDEX($W$8:$W$407,$AA10)=1,3=INDEX($X$8:$X$407,$AA10)+INDEX($V$8:$V$407,$AA10)),"S","R")))))) | AC10: =IF(OR($AB10="",$AB10="G"),"",IF($AB10="D",INDEX($U$8:$U$407,$AA10),IF($AB10="S",INDEX($T$8:$T$407,$AA10)&"|*",INDEX($S$8:$S$407,$AA10)&"|*"))) | AE10: =IF($U10="",0,COUNTIF(บันทึกรายเที่ยว!$T$6:$T$10005,$U10)) -> 0 | AF10: =IF($U10="",0,ROUND(SUMIF(บันทึกรายเที่ยว!$T$6:$T$10005,$U10,บันทึกรายเที่ยว!$J$6:$J$10005),2)) -> 0 | AG10: =IF($U10="",0,ROUND(SUMIF(บันทึกรายเที่ยว!$T$6:$T$10005,$U10,บันทึกรายเที่ยว!$K$6:$K$10005),2)) -> 0 | AH10: =IF($U10="",0,ROUND(SUMIF(บันทึกรายเที่ยว!$T$6:$T$10005,$U10,บันทึกรายเที่ยว!$M$6:$M$10005),2)) -> 0
A11: =IF($AB11="G","ผลรวมทั้งหมด",IF($AB11="R",INDEX($S$8:$S$407,$AA11),"")) | B11: =IF($AB11="S",INDEX($Y$8:$Y$407,$AA11),"") | C11: =IF($AB11="D",INDEX($Z$8:$Z$407,$AA11),"") | D11: =IF($AB11="G",SUM($AE$8:$AE$407),IF(OR($AB11="",$AB11="R"),"",IF($AB11="D",INDEX($AE$8:$AE$407,$AA11),SUMIF($T$8:$T$407,INDEX($T$8:$T$407,$AA11),$AE$8:$AE$407)))) | E11: =IF(4=$AD$1+3,"ขอแสดงความนับถือ",IF(4=$AD$1+6,"( )",IF(4=$AD$1+7,"เจ้าหน้าที่ขนส่ง",IF($AB11="G",SUM($AF$8:$AF$407),IF(OR($AB11="",$AB11="R"),"",IF($AB11="D",INDEX($AF$8:$AF$407,$AA11),SUMIF($T$8:$T$407,INDEX($T$8:$T$407,$AA11),$AF$8:$AF$407))))))) | F11: =IF($AB11="G",SUM($AG$8:$AG$407),IF(OR($AB11="",$AB11="R"),"",IF($AB11="D",INDEX($AG$8:$AG$407,$AA11),SUMIF($T$8:$T$407,INDEX($T$8:$T$407,$AA11),$AG$8:$AG$407)))) | G11: =IF(OR($AB11="",$AB11="R"),"",ROUND($E11-$F11,2)) | H11: =IF($AB11="G",SUM($AH$8:$AH$407),IF(OR($AB11="",$AB11="R"),"",IF($AB11="D",INDEX($AH$8:$AH$407,$AA11),SUMIF($T$8:$T$407,INDEX($T$8:$T$407,$AA11),$AH$8:$AH$407)))) | I11: พื้นที่ตาราง | J11: =IFERROR(MATCH(4,บันทึกรายเที่ยว!$W$6:$W$10005,0),"") | K11: =IF($J11="","",INDEX(บันทึกรายเที่ยว!$T$6:$T$10005,$J11)) | L11: =IF($J11="","",INDEX(บันทึกรายเที่ยว!$S$6:$S$10005,$J11)) | M11: =IF($J11="","",INDEX(บันทึกรายเที่ยว!$R$6:$R$10005,$J11)) | N11: =IF($J11="","",MATCH($M11,บันทึกรายเที่ยว!$R$6:$R$10005,0)) | O11: =IF($J11="","",MATCH($L11,บันทึกรายเที่ยว!$S$6:$S$10005,0)) | P11: =IF($J11="","",IF(AND(OR($I$3="(ทั้งหมด)",INDEX(บันทึกรายเที่ยว!$C$6:$C$10005,$J11)=$I$3),OR($I$5="(ทั้งหมด)",INDEX(บันทึกรายเที่ยว!$D$6:$D$10005,$J11)=$I$5),OR($I$7="(ทั้งหมด)",INDEX(บันทึกรายเที่ยว!$F$6:$F$10005,$J11)=$I$7)),$N11*10000000+$O11*1000+4,"")) | Q11: =IFERROR(MATCH(SMALL($P$8:$P$407,4),$P$8:$P$407,0),"") | R11: =IF($Q11="","",INDEX($J$8:$J$407,$Q11)) | S11: =IF($Q11="","",INDEX($M$8:$M$407,$Q11)) | T11: =IF($Q11="","",INDEX($L$8:$L$407,$Q11)) | U11: =IF($Q11="","",INDEX($K$8:$K$407,$Q11)) | V11: =IF($Q11="",0,IF($S11<>$S10,1,0)) -> 0 | W11: =IF($Q11="",0,IF($T11<>$T10,1,0)) -> 0 | X11: =IF($Q11="",99999+4,$X10+1+$V10+$W10) -> 100003 | Y11: =IF($Q11="","",INDEX(บันทึกรายเที่ยว!$Q$6:$Q$10005,$R11)) | Z11: =IF($Q11="","",INDEX(บันทึกรายเที่ยว!$F$6:$F$10005,$R11)) | AA11: =IFERROR(MATCH(4,$X$8:$X$407,1),"") | AB11: =IF(4=$AD$1+1,"G",IF($AA11="","",IF(INDEX($Q$8:$Q$407,$AA11)="","",IF(4>INDEX($X$8:$X$407,$AA11)+INDEX($V$8:$V$407,$AA11)+INDEX($W$8:$W$407,$AA11),"",IF(4=INDEX($X$8:$X$407,$AA11)+INDEX($V$8:$V$407,$AA11)+INDEX($W$8:$W$407,$AA11),"D",IF(AND(INDEX($W$8:$W$407,$AA11)=1,4=INDEX($X$8:$X$407,$AA11)+INDEX($V$8:$V$407,$AA11)),"S","R")))))) | AC11: =IF(OR($AB11="",$AB11="G"),"",IF($AB11="D",INDEX($U$8:$U$407,$AA11),IF($AB11="S",INDEX($T$8:$T$407,$AA11)&"|*",INDEX($S$8:$S$407,$AA11)&"|*"))) | AE11: =IF($U11="",0,COUNTIF(บันทึกรายเที่ยว!$T$6:$T$10005,$U11)) -> 0 | AF11: =IF($U11="",0,ROUND(SUMIF(บันทึกรายเที่ยว!$T$6:$T$10005,$U11,บันทึกรายเที่ยว!$J$6:$J$10005),2)) -> 0 | AG11: =IF($U11="",0,ROUND(SUMIF(บันทึกรายเที่ยว!$T$6:$T$10005,$U11,บันทึกรายเที่ยว!$K$6:$K$10005),2)) -> 0 | AH11: =IF($U11="",0,ROUND(SUMIF(บันทึกรายเที่ยว!$T$6:$T$10005,$U11,บันทึกรายเที่ยว!$M$6:$M$10005),2)) -> 0
A12: =IF($AB12="G","ผลรวมทั้งหมด",IF($AB12="R",INDEX($S$8:$S$407,$AA12),"")) | B12: =IF($AB12="S",INDEX($Y$8:$Y$407,$AA12),"") | C12: =IF($AB12="D",INDEX($Z$8:$Z$407,$AA12),"") | D12: =IF($AB12="G",SUM($AE$8:$AE$407),IF(OR($AB12="",$AB12="R"),"",IF($AB12="D",INDEX($AE$8:$AE$407,$AA12),SUMIF($T$8:$T$407,INDEX($T$8:$T$407,$AA12),$AE$8:$AE$407)))) | E12: =IF(5=$AD$1+3,"ขอแสดงความนับถือ",IF(5=$AD$1+6,"( )",IF(5=$AD$1+7,"เจ้าหน้าที่ขนส่ง",IF($AB12="G",SUM($AF$8:$AF$407),IF(OR($AB12="",$AB12="R"),"",IF($AB12="D",INDEX($AF$8:$AF$407,$AA12),SUMIF($T$8:$T$407,INDEX($T$8:$T$407,$AA12),$AF$8:$AF$407))))))) | F12: =IF($AB12="G",SUM($AG$8:$AG$407),IF(OR($AB12="",$AB12="R"),"",IF($AB12="D",INDEX($AG$8:$AG$407,$AA12),SUMIF($T$8:$T$407,INDEX($T$8:$T$407,$AA12),$AG$8:$AG$407)))) | G12: =IF(OR($AB12="",$AB12="R"),"",ROUND($E12-$F12,2)) | H12: =IF($AB12="G",SUM($AH$8:$AH$407),IF(OR($AB12="",$AB12="R"),"",IF($AB12="D",INDEX($AH$8:$AH$407,$AA12),SUMIF($T$8:$T$407,INDEX($T$8:$T$407,$AA12),$AH$8:$AH$407)))) | I12: =IF($AB$707<>"","*** บรรทัดไม่พอ แยกไฟล์ ***",IF($AD$1+7>200,"*** ยาวกว่าพื้นที่พิมพ์ ตั้ง Print Area ใหม่ ***","เพียงพอ")) -> เพียงพอ | J12: =IFERROR(MATCH(5,บันทึกรายเที่ยว!$W$6:$W$10005,0),"") | K12: =IF($J12="","",INDEX(บันทึกรายเที่ยว!$T$6:$T$10005,$J12)) | L12: =IF($J12="","",INDEX(บันทึกรายเที่ยว!$S$6:$S$10005,$J12)) | M12: =IF($J12="","",INDEX(บันทึกรายเที่ยว!$R$6:$R$10005,$J12)) | N12: =IF($J12="","",MATCH($M12,บันทึกรายเที่ยว!$R$6:$R$10005,0)) | O12: =IF($J12="","",MATCH($L12,บันทึกรายเที่ยว!$S$6:$S$10005,0)) | P12: =IF($J12="","",IF(AND(OR($I$3="(ทั้งหมด)",INDEX(บันทึกรายเที่ยว!$C$6:$C$10005,$J12)=$I$3),OR($I$5="(ทั้งหมด)",INDEX(บันทึกรายเที่ยว!$D$6:$D$10005,$J12)=$I$5),OR($I$7="(ทั้งหมด)",INDEX(บันทึกรายเที่ยว!$F$6:$F$10005,$J12)=$I$7)),$N12*10000000+$O12*1000+5,"")) | Q12: =IFERROR(MATCH(SMALL($P$8:$P$407,5),$P$8:$P$407,0),"") | R12: =IF($Q12="","",INDEX($J$8:$J$407,$Q12)) | S12: =IF($Q12="","",INDEX($M$8:$M$407,$Q12)) | T12: =IF($Q12="","",INDEX($L$8:$L$407,$Q12)) | U12: =IF($Q12="","",INDEX($K$8:$K$407,$Q12)) | V12: =IF($Q12="",0,IF($S12<>$S11,1,0)) -> 0 | W12: =IF($Q12="",0,IF($T12<>$T11,1,0)) -> 0 | X12: =IF($Q12="",99999+5,$X11+1+$V11+$W11) -> 100004 | Y12: =IF($Q12="","",INDEX(บันทึกรายเที่ยว!$Q$6:$Q$10005,$R12)) | Z12: =IF($Q12="","",INDEX(บันทึกรายเที่ยว!$F$6:$F$10005,$R12)) | AA12: =IFERROR(MATCH(5,$X$8:$X$407,1),"") | AB12: =IF(5=$AD$1+1,"G",IF($AA12="","",IF(INDEX($Q$8:$Q$407,$AA12)="","",IF(5>INDEX($X$8:$X$407,$AA12)+INDEX($V$8:$V$407,$AA12)+INDEX($W$8:$W$407,$AA12),"",IF(5=INDEX($X$8:$X$407,$AA12)+INDEX($V$8:$V$407,$AA12)+INDEX($W$8:$W$407,$AA12),"D",IF(AND(INDEX($W$8:$W$407,$AA12)=1,5=INDEX($X$8:$X$407,$AA12)+INDEX($V$8:$V$407,$AA12)),"S","R")))))) | AC12: =IF(OR($AB12="",$AB12="G"),"",IF($AB12="D",INDEX($U$8:$U$407,$AA12),IF($AB12="S",INDEX($T$8:$T$407,$AA12)&"|*",INDEX($S$8:$S$407,$AA12)&"|*"))) | AE12: =IF($U12="",0,COUNTIF(บันทึกรายเที่ยว!$T$6:$T$10005,$U12)) -> 0 | AF12: =IF($U12="",0,ROUND(SUMIF(บันทึกรายเที่ยว!$T$6:$T$10005,$U12,บันทึกรายเที่ยว!$J$6:$J$10005),2)) -> 0 | AG12: =IF($U12="",0,ROUND(SUMIF(บันทึกรายเที่ยว!$T$6:$T$10005,$U12,บันทึกรายเที่ยว!$K$6:$K$10005),2)) -> 0 | AH12: =IF($U12="",0,ROUND(SUMIF(บันทึกรายเที่ยว!$T$6:$T$10005,$U12,บันทึกรายเที่ยว!$M$6:$M$10005),2)) -> 0
A13: =IF($AB13="G","ผลรวมทั้งหมด",IF($AB13="R",INDEX($S$8:$S$407,$AA13),"")) | B13: =IF($AB13="S",INDEX($Y$8:$Y$407,$AA13),"") | C13: =IF($AB13="D",INDEX($Z$8:$Z$407,$AA13),"") | D13: =IF($AB13="G",SUM($AE$8:$AE$407),IF(OR($AB13="",$AB13="R"),"",IF($AB13="D",INDEX($AE$8:$AE$407,$AA13),SUMIF($T$8:$T$407,INDEX($T$8:$T$407,$AA13),$AE$8:$AE$407)))) | E13: =IF(6=$AD$1+3,"ขอแสดงความนับถือ",IF(6=$AD$1+6,"( )",IF(6=$AD$1+7,"เจ้าหน้าที่ขนส่ง",IF($AB13="G",SUM($AF$8:$AF$407),IF(OR($AB13="",$AB13="R"),"",IF($AB13="D",INDEX($AF$8:$AF$407,$AA13),SUMIF($T$8:$T$407,INDEX($T$8:$T$407,$AA13),$AF$8:$AF$407))))))) -> ( ) | F13: =IF($AB13="G",SUM($AG$8:$AG$407),IF(OR($AB13="",$AB13="R"),"",IF($AB13="D",INDEX($AG$8:$AG$407,$AA13),SUMIF($T$8:$T$407,INDEX($T$8:$T$407,$AA13),$AG$8:$AG$407)))) | G13: =IF(OR($AB13="",$AB13="R"),"",ROUND($E13-$F13,2)) | H13: =IF($AB13="G",SUM($AH$8:$AH$407),IF(OR($AB13="",$AB13="R"),"",IF($AB13="D",INDEX($AH$8:$AH$407,$AA13),SUMIF($T$8:$T$407,INDEX($T$8:$T$407,$AA13),$AH$8:$AH$407)))) | I13: ช่วงพิมพ์ที่พอดี | J13: =IFERROR(MATCH(6,บันทึกรายเที่ยว!$W$6:$W$10005,0),"") | K13: =IF($J13="","",INDEX(บันทึกรายเที่ยว!$T$6:$T$10005,$J13)) | L13: =IF($J13="","",INDEX(บันทึกรายเที่ยว!$S$6:$S$10005,$J13)) | M13: =IF($J13="","",INDEX(บันทึกรายเที่ยว!$R$6:$R$10005,$J13)) | N13: =IF($J13="","",MATCH($M13,บันทึกรายเที่ยว!$R$6:$R$10005,0)) | O13: =IF($J13="","",MATCH($L13,บันทึกรายเที่ยว!$S$6:$S$10005,0)) | P13: =IF($J13="","",IF(AND(OR($I$3="(ทั้งหมด)",INDEX(บันทึกรายเที่ยว!$C$6:$C$10005,$J13)=$I$3),OR($I$5="(ทั้งหมด)",INDEX(บันทึกรายเที่ยว!$D$6:$D$10005,$J13)=$I$5),OR($I$7="(ทั้งหมด)",INDEX(บันทึกรายเที่ยว!$F$6:$F$10005,$J13)=$I$7)),$N13*10000000+$O13*1000+6,"")) | Q13: =IFERROR(MATCH(SMALL($P$8:$P$407,6),$P$8:$P$407,0),"") | R13: =IF($Q13="","",INDEX($J$8:$J$407,$Q13)) | S13: =IF($Q13="","",INDEX($M$8:$M$407,$Q13)) | T13: =IF($Q13="","",INDEX($L$8:$L$407,$Q13)) | U13: =IF($Q13="","",INDEX($K$8:$K$407,$Q13)) | V13: =IF($Q13="",0,IF($S13<>$S12,1,0)) -> 0 | W13: =IF($Q13="",0,IF($T13<>$T12,1,0)) -> 0 | X13: =IF($Q13="",99999+6,$X12+1+$V12+$W12) -> 100005 | Y13: =IF($Q13="","",INDEX(บันทึกรายเที่ยว!$Q$6:$Q$10005,$R13)) | Z13: =IF($Q13="","",INDEX(บันทึกรายเที่ยว!$F$6:$F$10005,$R13)) | AA13: =IFERROR(MATCH(6,$X$8:$X$407,1),"") | AB13: =IF(6=$AD$1+1,"G",IF($AA13="","",IF(INDEX($Q$8:$Q$407,$AA13)="","",IF(6>INDEX($X$8:$X$407,$AA13)+INDEX($V$8:$V$407,$AA13)+INDEX($W$8:$W$407,$AA13),"",IF(6=INDEX($X$8:$X$407,$AA13)+INDEX($V$8:$V$407,$AA13)+INDEX($W$8:$W$407,$AA13),"D",IF(AND(INDEX($W$8:$W$407,$AA13)=1,6=INDEX($X$8:$X$407,$AA13)+INDEX($V$8:$V$407,$AA13)),"S","R")))))) | AC13: =IF(OR($AB13="",$AB13="G"),"",IF($AB13="D",INDEX($U$8:$U$407,$AA13),IF($AB13="S",INDEX($T$8:$T$407,$AA13)&"|*",INDEX($S$8:$S$407,$AA13)&"|*"))) | AE13: =IF($U13="",0,COUNTIF(บันทึกรายเที่ยว!$T$6:$T$10005,$U13)) -> 0 | AF13: =IF($U13="",0,ROUND(SUMIF(บันทึกรายเที่ยว!$T$6:$T$10005,$U13,บันทึกรายเที่ยว!$J$6:$J$10005),2)) -> 0 | AG13: =IF($U13="",0,ROUND(SUMIF(บันทึกรายเที่ยว!$T$6:$T$10005,$U13,บันทึกรายเที่ยว!$K$6:$K$10005),2)) -> 0 | AH13: =IF($U13="",0,ROUND(SUMIF(บันทึกรายเที่ยว!$T$6:$T$10005,$U13,บันทึกรายเที่ยว!$M$6:$M$10005),2)) -> 0
A14: =IF($AB14="G","ผลรวมทั้งหมด",IF($AB14="R",INDEX($S$8:$S$407,$AA14),"")) | B14: =IF($AB14="S",INDEX($Y$8:$Y$407,$AA14),"") | C14: =IF($AB14="D",INDEX($Z$8:$Z$407,$AA14),"") | D14: =IF($AB14="G",SUM($AE$8:$AE$407),IF(OR($AB14="",$AB14="R"),"",IF($AB14="D",INDEX($AE$8:$AE$407,$AA14),SUMIF($T$8:$T$407,INDEX($T$8:$T$407,$AA14),$AE$8:$AE$407)))) | E14: =IF(7=$AD$1+3,"ขอแสดงความนับถือ",IF(7=$AD$1+6,"( )",IF(7=$AD$1+7,"เจ้าหน้าที่ขนส่ง",IF($AB14="G",SUM($AF$8:$AF$407),IF(OR($AB14="",$AB14="R"),"",IF($AB14="D",INDEX($AF$8:$AF$407,$AA14),SUMIF($T$8:$T$407,INDEX($T$8:$T$407,$AA14),$AF$8:$AF$407))))))) -> เจ้าหน้าที่ขนส่ง | F14: =IF($AB14="G",SUM($AG$8:$AG$407),IF(OR($AB14="",$AB14="R"),"",IF($AB14="D",INDEX($AG$8:$AG$407,$AA14),SUMIF($T$8:$T$407,INDEX($T$8:$T$407,$AA14),$AG$8:$AG$407)))) | G14: =IF(OR($AB14="",$AB14="R"),"",ROUND($E14-$F14,2)) | H14: =IF($AB14="G",SUM($AH$8:$AH$407),IF(OR($AB14="",$AB14="R"),"",IF($AB14="D",INDEX($AH$8:$AH$407,$AA14),SUMIF($T$8:$T$407,INDEX($T$8:$T$407,$AA14),$AH$8:$AH$407)))) | I14: ="A1:H"&(8-1+$AD$1+7) -> A1:H14 | J14: =IFERROR(MATCH(7,บันทึกรายเที่ยว!$W$6:$W$10005,0),"") | K14: =IF($J14="","",INDEX(บันทึกรายเที่ยว!$T$6:$T$10005,$J14)) | L14: =IF($J14="","",INDEX(บันทึกรายเที่ยว!$S$6:$S$10005,$J14)) | M14: =IF($J14="","",INDEX(บันทึกรายเที่ยว!$R$6:$R$10005,$J14)) | N14: =IF($J14="","",MATCH($M14,บันทึกรายเที่ยว!$R$6:$R$10005,0)) | O14: =IF($J14="","",MATCH($L14,บันทึกรายเที่ยว!$S$6:$S$10005,0)) | P14: =IF($J14="","",IF(AND(OR($I$3="(ทั้งหมด)",INDEX(บันทึกรายเที่ยว!$C$6:$C$10005,$J14)=$I$3),OR($I$5="(ทั้งหมด)",INDEX(บันทึกรายเที่ยว!$D$6:$D$10005,$J14)=$I$5),OR($I$7="(ทั้งหมด)",INDEX(บันทึกรายเที่ยว!$F$6:$F$10005,$J14)=$I$7)),$N14*10000000+$O14*1000+7,"")) | Q14: =IFERROR(MATCH(SMALL($P$8:$P$407,7),$P$8:$P$407,0),"") | R14: =IF($Q14="","",INDEX($J$8:$J$407,$Q14)) | S14: =IF($Q14="","",INDEX($M$8:$M$407,$Q14)) | T14: =IF($Q14="","",INDEX($L$8:$L$407,$Q14)) | U14: =IF($Q14="","",INDEX($K$8:$K$407,$Q14)) | V14: =IF($Q14="",0,IF($S14<>$S13,1,0)) -> 0 | W14: =IF($Q14="",0,IF($T14<>$T13,1,0)) -> 0 | X14: =IF($Q14="",99999+7,$X13+1+$V13+$W13) -> 100006 | Y14: =IF($Q14="","",INDEX(บันทึกรายเที่ยว!$Q$6:$Q$10005,$R14)) | Z14: =IF($Q14="","",INDEX(บันทึกรายเที่ยว!$F$6:$F$10005,$R14)) | AA14: =IFERROR(MATCH(7,$X$8:$X$407,1),"") | AB14: =IF(7=$AD$1+1,"G",IF($AA14="","",IF(INDEX($Q$8:$Q$407,$AA14)="","",IF(7>INDEX($X$8:$X$407,$AA14)+INDEX($V$8:$V$407,$AA14)+INDEX($W$8:$W$407,$AA14),"",IF(7=INDEX($X$8:$X$407,$AA14)+INDEX($V$8:$V$407,$AA14)+INDEX($W$8:$W$407,$AA14),"D",IF(AND(INDEX($W$8:$W$407,$AA14)=1,7=INDEX($X$8:$X$407,$AA14)+INDEX($V$8:$V$407,$AA14)),"S","R")))))) | AC14: =IF(OR($AB14="",$AB14="G"),"",IF($AB14="D",INDEX($U$8:$U$407,$AA14),IF($AB14="S",INDEX($T$8:$T$407,$AA14)&"|*",INDEX($S$8:$S$407,$AA14)&"|*"))) | AE14: =IF($U14="",0,COUNTIF(บันทึกรายเที่ยว!$T$6:$T$10005,$U14)) -> 0 | AF14: =IF($U14="",0,ROUND(SUMIF(บันทึกรายเที่ยว!$T$6:$T$10005,$U14,บันทึกรายเที่ยว!$J$6:$J$10005),2)) -> 0 | AG14: =IF($U14="",0,ROUND(SUMIF(บันทึกรายเที่ยว!$T$6:$T$10005,$U14,บันทึกรายเที่ยว!$K$6:$K$10005),2)) -> 0 | AH14: =IF($U14="",0,ROUND(SUMIF(บันทึกรายเที่ยว!$T$6:$T$10005,$U14,บันทึกรายเที่ยว!$M$6:$M$10005),2)) -> 0
